Internal Server Error: /dashboard/
Traceback (most recent call last):
  File "D:\Project\venv\Lib\site-packages\django\core\handlers\exception.py", line 55, in inner
    response = get_response(request)
  File "D:\Project\venv\Lib\site-packages\django\core\handlers\base.py", line 197, in _get_response
    response = wrapped_callback(request, *callback_args, **callback_kwargs)
  File "D:\Project\venv\Lib\site-packages\django\views\decorators\csrf.py", line 65, in _view_wrapper
    return view_func(request, *args, **kwargs)
  File "D:\Project\venv\Lib\site-packages\django\views\generic\base.py", line 104, in view
    return self.dispatch(request, *args, **kwargs)
           ~~~~~~~~~~~~~^^^^^^^^^^^^^^^^^^^^^^^^^^
  File "D:\Project\venv\Lib\site-packages\rest_framework\views.py", line 515, in dispatch
    response = self.handle_exception(exc)
  File "D:\Project\venv\Lib\site-packages\rest_framework\views.py", line 475, in handle_exception
    self.raise_uncaught_exception(exc)
    ~~~~~~~~~~~~~~~~~~~~~~~~~~~~~^^^^^
  File "D:\Project\venv\Lib\site-packages\rest_framework\views.py", line 486, in raise_uncaught_exception
    raise exc
  File "D:\Project\venv\Lib\site-packages\rest_framework\views.py", line 512, in dispatch
    response = handler(request, *args, **kwargs)
  File "D:\Project\venv\Lib\site-packages\rest_framework\decorators.py", line 50, in handler
    return func(*args, **kwargs)
  File "D:\Project\base\views.py", line 83, in dashboard
    groups = [{"id": group.id, "name": group.name} for group in user.group_set.all()]
                                                                ^^^^^^^^^^^^^^
AttributeError: 'Staffs' object has no attribute 'group_set'. Did you mean: 'groups'?
"GET /dashboard/ HTTP/1.1" 500 102772
Internal Server Error: /dashboard/
Traceback (most recent call last):
  File "D:\Project\venv\Lib\site-packages\django\core\handlers\exception.py", line 55, in inner
    response = get_response(request)
  File "D:\Project\venv\Lib\site-packages\django\core\handlers\base.py", line 197, in _get_response
    response = wrapped_callback(request, *callback_args, **callback_kwargs)
  File "D:\Project\venv\Lib\site-packages\django\views\decorators\csrf.py", line 65, in _view_wrapper
    return view_func(request, *args, **kwargs)
  File "D:\Project\venv\Lib\site-packages\django\views\generic\base.py", line 104, in view
    return self.dispatch(request, *args, **kwargs)
           ~~~~~~~~~~~~~^^^^^^^^^^^^^^^^^^^^^^^^^^
  File "D:\Project\venv\Lib\site-packages\rest_framework\views.py", line 515, in dispatch
    response = self.handle_exception(exc)
  File "D:\Project\venv\Lib\site-packages\rest_framework\views.py", line 475, in handle_exception
    self.raise_uncaught_exception(exc)
    ~~~~~~~~~~~~~~~~~~~~~~~~~~~~~^^^^^
  File "D:\Project\venv\Lib\site-packages\rest_framework\views.py", line 486, in raise_uncaught_exception
    raise exc
  File "D:\Project\venv\Lib\site-packages\rest_framework\views.py", line 512, in dispatch
    response = handler(request, *args, **kwargs)
  File "D:\Project\venv\Lib\site-packages\rest_framework\decorators.py", line 50, in handler
    return func(*args, **kwargs)
  File "D:\Project\base\views.py", line 83, in dashboard
    groups = [{"id": group.id, "name": group.name} for group in user.group_set.all()]
                                                                ^^^^^^^^^^^^^^
AttributeError: 'Staffs' object has no attribute 'group_set'. Did you mean: 'groups'?
"GET /dashboard/ HTTP/1.1" 500 102772
Internal Server Error: /dashboard/
Traceback (most recent call last):
  File "D:\Project\venv\Lib\site-packages\django\core\handlers\exception.py", line 55, in inner
    response = get_response(request)
  File "D:\Project\venv\Lib\site-packages\django\core\handlers\base.py", line 197, in _get_response
    response = wrapped_callback(request, *callback_args, **callback_kwargs)
  File "D:\Project\venv\Lib\site-packages\django\views\decorators\csrf.py", line 65, in _view_wrapper
    return view_func(request, *args, **kwargs)
  File "D:\Project\venv\Lib\site-packages\django\views\generic\base.py", line 104, in view
    return self.dispatch(request, *args, **kwargs)
           ~~~~~~~~~~~~~^^^^^^^^^^^^^^^^^^^^^^^^^^
  File "D:\Project\venv\Lib\site-packages\rest_framework\views.py", line 515, in dispatch
    response = self.handle_exception(exc)
  File "D:\Project\venv\Lib\site-packages\rest_framework\views.py", line 475, in handle_exception
    self.raise_uncaught_exception(exc)
    ~~~~~~~~~~~~~~~~~~~~~~~~~~~~~^^^^^
  File "D:\Project\venv\Lib\site-packages\rest_framework\views.py", line 486, in raise_uncaught_exception
    raise exc
  File "D:\Project\venv\Lib\site-packages\rest_framework\views.py", line 512, in dispatch
    response = handler(request, *args, **kwargs)
  File "D:\Project\venv\Lib\site-packages\rest_framework\decorators.py", line 50, in handler
    return func(*args, **kwargs)
  File "D:\Project\base\views.py", line 83, in dashboard
    groups = [{"id": group.id, "name": group.name} for group in user.group_set.all()]
                                                                ^^^^^^^^^^^^^^
AttributeError: 'Staffs' object has no attribute 'group_set'. Did you mean: 'groups'?
"GET /dashboard/ HTTP/1.1" 500 102772
Internal Server Error: /dashboard/
Traceback (most recent call last):
  File "D:\Project\venv\Lib\site-packages\django\db\backends\utils.py", line 105, in _execute
    return self.cursor.execute(sql, params)
           ~~~~~~~~~~~~~~~~~~~^^^^^^^^^^^^^
  File "D:\Project\venv\Lib\site-packages\django\db\backends\mysql\base.py", line 76, in execute
    return self.cursor.execute(query, args)
           ~~~~~~~~~~~~~~~~~~~^^^^^^^^^^^^^
  File "D:\Project\venv\Lib\site-packages\MySQLdb\cursors.py", line 179, in execute
    res = self._query(mogrified_query)
  File "D:\Project\venv\Lib\site-packages\MySQLdb\cursors.py", line 330, in _query
    db.query(q)
    ~~~~~~~~^^^
  File "D:\Project\venv\Lib\site-packages\MySQLdb\connections.py", line 280, in query
    _mysql.connection.query(self, query)
    ~~~~~~~~~~~~~~~~~~~~~~~^^^^^^^^^^^^^
MySQLdb.ProgrammingError: (1146, "Table 'demo.base_group_teachers' doesn't exist")

The above exception was the direct cause of the following exception:

Traceback (most recent call last):
  File "D:\Project\venv\Lib\site-packages\django\core\handlers\exception.py", line 55, in inner
    response = get_response(request)
  File "D:\Project\venv\Lib\site-packages\django\core\handlers\base.py", line 197, in _get_response
    response = wrapped_callback(request, *callback_args, **callback_kwargs)
  File "D:\Project\venv\Lib\site-packages\django\views\decorators\csrf.py", line 65, in _view_wrapper
    return view_func(request, *args, **kwargs)
  File "D:\Project\venv\Lib\site-packages\django\views\generic\base.py", line 104, in view
    return self.dispatch(request, *args, **kwargs)
           ~~~~~~~~~~~~~^^^^^^^^^^^^^^^^^^^^^^^^^^
  File "D:\Project\venv\Lib\site-packages\rest_framework\views.py", line 515, in dispatch
    response = self.handle_exception(exc)
  File "D:\Project\venv\Lib\site-packages\rest_framework\views.py", line 475, in handle_exception
    self.raise_uncaught_exception(exc)
    ~~~~~~~~~~~~~~~~~~~~~~~~~~~~~^^^^^
  File "D:\Project\venv\Lib\site-packages\rest_framework\views.py", line 486, in raise_uncaught_exception
    raise exc
  File "D:\Project\venv\Lib\site-packages\rest_framework\views.py", line 512, in dispatch
    response = handler(request, *args, **kwargs)
  File "D:\Project\venv\Lib\site-packages\rest_framework\decorators.py", line 50, in handler
    return func(*args, **kwargs)
  File "D:\Project\base\views.py", line 86, in dashboard
    groups = [{"id": group.id, "name": group.name} for group in Group.objects.filter(teachers=user)]
                                                                ~~~~~~~~~~~~~~~~~~~~^^^^^^^^^^^^^^^
  File "D:\Project\venv\Lib\site-packages\django\db\models\query.py", line 400, in __iter__
    self._fetch_all()
    ~~~~~~~~~~~~~~~^^
  File "D:\Project\venv\Lib\site-packages\django\db\models\query.py", line 1928, in _fetch_all
    self._result_cache = list(self._iterable_class(self))
                         ~~~~^^^^^^^^^^^^^^^^^^^^^^^^^^^^
  File "D:\Project\venv\Lib\site-packages\django\db\models\query.py", line 91, in __iter__
    results = compiler.execute_sql(
        chunked_fetch=self.chunked_fetch, chunk_size=self.chunk_size
    )
  File "D:\Project\venv\Lib\site-packages\django\db\models\sql\compiler.py", line 1574, in execute_sql
    cursor.execute(sql, params)
    ~~~~~~~~~~~~~~^^^^^^^^^^^^^
  File "D:\Project\venv\Lib\site-packages\django\db\backends\utils.py", line 122, in execute
    return super().execute(sql, params)
           ~~~~~~~~~~~~~~~^^^^^^^^^^^^^
  File "D:\Project\venv\Lib\site-packages\django\db\backends\utils.py", line 79, in execute
    return self._execute_with_wrappers(
           ~~~~~~~~~~~~~~~~~~~~~~~~~~~^
        sql, params, many=False, executor=self._execute
        ^^^^^^^^^^^^^^^^^^^^^^^^^^^^^^^^^^^^^^^^^^^^^^^
    )
    ^
  File "D:\Project\venv\Lib\site-packages\django\db\backends\utils.py", line 92, in _execute_with_wrappers
    return executor(sql, params, many, context)
  File "D:\Project\venv\Lib\site-packages\django\db\backends\utils.py", line 100, in _execute
    with self.db.wrap_database_errors:
         ^^^^^^^^^^^^^^^^^^^^^^^^^^^^
  File "D:\Project\venv\Lib\site-packages\django\db\utils.py", line 91, in __exit__
    raise dj_exc_value.with_traceback(traceback) from exc_value
  File "D:\Project\venv\Lib\site-packages\django\db\backends\utils.py", line 105, in _execute
    return self.cursor.execute(sql, params)
           ~~~~~~~~~~~~~~~~~~~^^^^^^^^^^^^^
  File "D:\Project\venv\Lib\site-packages\django\db\backends\mysql\base.py", line 76, in execute
    return self.cursor.execute(query, args)
           ~~~~~~~~~~~~~~~~~~~^^^^^^^^^^^^^
  File "D:\Project\venv\Lib\site-packages\MySQLdb\cursors.py", line 179, in execute
    res = self._query(mogrified_query)
  File "D:\Project\venv\Lib\site-packages\MySQLdb\cursors.py", line 330, in _query
    db.query(q)
    ~~~~~~~~^^^
  File "D:\Project\venv\Lib\site-packages\MySQLdb\connections.py", line 280, in query
    _mysql.connection.query(self, query)
    ~~~~~~~~~~~~~~~~~~~~~~~^^^^^^^^^^^^^
django.db.utils.ProgrammingError: (1146, "Table 'demo.base_group_teachers' doesn't exist")
"GET /dashboard/ HTTP/1.1" 500 190143
Internal Server Error: /dashboard/
Traceback (most recent call last):
  File "D:\Project\venv\Lib\site-packages\django\db\backends\utils.py", line 105, in _execute
    return self.cursor.execute(sql, params)
           ~~~~~~~~~~~~~~~~~~~^^^^^^^^^^^^^
  File "D:\Project\venv\Lib\site-packages\django\db\backends\mysql\base.py", line 76, in execute
    return self.cursor.execute(query, args)
           ~~~~~~~~~~~~~~~~~~~^^^^^^^^^^^^^
  File "D:\Project\venv\Lib\site-packages\MySQLdb\cursors.py", line 179, in execute
    res = self._query(mogrified_query)
  File "D:\Project\venv\Lib\site-packages\MySQLdb\cursors.py", line 330, in _query
    db.query(q)
    ~~~~~~~~^^^
  File "D:\Project\venv\Lib\site-packages\MySQLdb\connections.py", line 280, in query
    _mysql.connection.query(self, query)
    ~~~~~~~~~~~~~~~~~~~~~~~^^^^^^^^^^^^^
MySQLdb.ProgrammingError: (1146, "Table 'demo.base_group_teachers' doesn't exist")

The above exception was the direct cause of the following exception:

Traceback (most recent call last):
  File "D:\Project\venv\Lib\site-packages\django\core\handlers\exception.py", line 55, in inner
    response = get_response(request)
  File "D:\Project\venv\Lib\site-packages\django\core\handlers\base.py", line 197, in _get_response
    response = wrapped_callback(request, *callback_args, **callback_kwargs)
  File "D:\Project\venv\Lib\site-packages\django\views\decorators\csrf.py", line 65, in _view_wrapper
    return view_func(request, *args, **kwargs)
  File "D:\Project\venv\Lib\site-packages\django\views\generic\base.py", line 104, in view
    return self.dispatch(request, *args, **kwargs)
           ~~~~~~~~~~~~~^^^^^^^^^^^^^^^^^^^^^^^^^^
  File "D:\Project\venv\Lib\site-packages\rest_framework\views.py", line 515, in dispatch
    response = self.handle_exception(exc)
  File "D:\Project\venv\Lib\site-packages\rest_framework\views.py", line 475, in handle_exception
    self.raise_uncaught_exception(exc)
    ~~~~~~~~~~~~~~~~~~~~~~~~~~~~~^^^^^
  File "D:\Project\venv\Lib\site-packages\rest_framework\views.py", line 486, in raise_uncaught_exception
    raise exc
  File "D:\Project\venv\Lib\site-packages\rest_framework\views.py", line 512, in dispatch
    response = handler(request, *args, **kwargs)
  File "D:\Project\venv\Lib\site-packages\rest_framework\decorators.py", line 50, in handler
    return func(*args, **kwargs)
  File "D:\Project\base\views.py", line 86, in dashboard
    groups = [{"id": group.id, "name": group.name} for group in Group.objects.filter(teachers=user)]
                                                                ~~~~~~~~~~~~~~~~~~~~^^^^^^^^^^^^^^^
  File "D:\Project\venv\Lib\site-packages\django\db\models\query.py", line 400, in __iter__
    self._fetch_all()
    ~~~~~~~~~~~~~~~^^
  File "D:\Project\venv\Lib\site-packages\django\db\models\query.py", line 1928, in _fetch_all
    self._result_cache = list(self._iterable_class(self))
                         ~~~~^^^^^^^^^^^^^^^^^^^^^^^^^^^^
  File "D:\Project\venv\Lib\site-packages\django\db\models\query.py", line 91, in __iter__
    results = compiler.execute_sql(
        chunked_fetch=self.chunked_fetch, chunk_size=self.chunk_size
    )
  File "D:\Project\venv\Lib\site-packages\django\db\models\sql\compiler.py", line 1574, in execute_sql
    cursor.execute(sql, params)
    ~~~~~~~~~~~~~~^^^^^^^^^^^^^
  File "D:\Project\venv\Lib\site-packages\django\db\backends\utils.py", line 122, in execute
    return super().execute(sql, params)
           ~~~~~~~~~~~~~~~^^^^^^^^^^^^^
  File "D:\Project\venv\Lib\site-packages\django\db\backends\utils.py", line 79, in execute
    return self._execute_with_wrappers(
           ~~~~~~~~~~~~~~~~~~~~~~~~~~~^
        sql, params, many=False, executor=self._execute
        ^^^^^^^^^^^^^^^^^^^^^^^^^^^^^^^^^^^^^^^^^^^^^^^
    )
    ^
  File "D:\Project\venv\Lib\site-packages\django\db\backends\utils.py", line 92, in _execute_with_wrappers
    return executor(sql, params, many, context)
  File "D:\Project\venv\Lib\site-packages\django\db\backends\utils.py", line 100, in _execute
    with self.db.wrap_database_errors:
         ^^^^^^^^^^^^^^^^^^^^^^^^^^^^
  File "D:\Project\venv\Lib\site-packages\django\db\utils.py", line 91, in __exit__
    raise dj_exc_value.with_traceback(traceback) from exc_value
  File "D:\Project\venv\Lib\site-packages\django\db\backends\utils.py", line 105, in _execute
    return self.cursor.execute(sql, params)
           ~~~~~~~~~~~~~~~~~~~^^^^^^^^^^^^^
  File "D:\Project\venv\Lib\site-packages\django\db\backends\mysql\base.py", line 76, in execute
    return self.cursor.execute(query, args)
           ~~~~~~~~~~~~~~~~~~~^^^^^^^^^^^^^
  File "D:\Project\venv\Lib\site-packages\MySQLdb\cursors.py", line 179, in execute
    res = self._query(mogrified_query)
  File "D:\Project\venv\Lib\site-packages\MySQLdb\cursors.py", line 330, in _query
    db.query(q)
    ~~~~~~~~^^^
  File "D:\Project\venv\Lib\site-packages\MySQLdb\connections.py", line 280, in query
    _mysql.connection.query(self, query)
    ~~~~~~~~~~~~~~~~~~~~~~~^^^^^^^^^^^^^
django.db.utils.ProgrammingError: (1146, "Table 'demo.base_group_teachers' doesn't exist")
"GET /dashboard/ HTTP/1.1" 500 190143
Internal Server Error: /dashboard/
Traceback (most recent call last):
  File "D:\Project\venv\Lib\site-packages\django\core\handlers\exception.py", line 55, in inner
    response = get_response(request)
  File "D:\Project\venv\Lib\site-packages\django\core\handlers\base.py", line 197, in _get_response
    response = wrapped_callback(request, *callback_args, **callback_kwargs)
  File "D:\Project\venv\Lib\site-packages\django\views\decorators\csrf.py", line 65, in _view_wrapper
    return view_func(request, *args, **kwargs)
  File "D:\Project\venv\Lib\site-packages\django\views\generic\base.py", line 104, in view
    return self.dispatch(request, *args, **kwargs)
           ~~~~~~~~~~~~~^^^^^^^^^^^^^^^^^^^^^^^^^^
  File "D:\Project\venv\Lib\site-packages\rest_framework\views.py", line 515, in dispatch
    response = self.handle_exception(exc)
  File "D:\Project\venv\Lib\site-packages\rest_framework\views.py", line 475, in handle_exception
    self.raise_uncaught_exception(exc)
    ~~~~~~~~~~~~~~~~~~~~~~~~~~~~~^^^^^
  File "D:\Project\venv\Lib\site-packages\rest_framework\views.py", line 486, in raise_uncaught_exception
    raise exc
  File "D:\Project\venv\Lib\site-packages\rest_framework\views.py", line 512, in dispatch
    response = handler(request, *args, **kwargs)
  File "D:\Project\venv\Lib\site-packages\rest_framework\decorators.py", line 50, in handler
    return func(*args, **kwargs)
  File "D:\Project\base\views.py", line 86, in dashboard
    groups = [{"id": group.id, "name": group.name} for group in Group.objects.filter(staffs=user)]
                                                                ~~~~~~~~~~~~~~~~~~~~^^^^^^^^^^^^^
  File "D:\Project\venv\Lib\site-packages\django\db\models\manager.py", line 87, in manager_method
    return getattr(self.get_queryset(), name)(*args, **kwargs)
           ~~~~~~~~~~~~~~~~~~~~~~~~~~~~~~~~~~^^^^^^^^^^^^^^^^^
  File "D:\Project\venv\Lib\site-packages\django\db\models\query.py", line 1476, in filter
    return self._filter_or_exclude(False, args, kwargs)
           ~~~~~~~~~~~~~~~~~~~~~~~^^^^^^^^^^^^^^^^^^^^^
  File "D:\Project\venv\Lib\site-packages\django\db\models\query.py", line 1494, in _filter_or_exclude
    clone._filter_or_exclude_inplace(negate, args, kwargs)
    ~~~~~~~~~~~~~~~~~~~~~~~~~~~~~~~~^^^^^^^^^^^^^^^^^^^^^^
  File "D:\Project\venv\Lib\site-packages\django\db\models\query.py", line 1501, in _filter_or_exclude_inplace
    self._query.add_q(Q(*args, **kwargs))
    ~~~~~~~~~~~~~~~~~^^^^^^^^^^^^^^^^^^^^
  File "D:\Project\venv\Lib\site-packages\django\db\models\sql\query.py", line 1609, in add_q
    clause, _ = self._add_q(q_object, self.used_aliases)
                ~~~~~~~~~~~^^^^^^^^^^^^^^^^^^^^^^^^^^^^^
  File "D:\Project\venv\Lib\site-packages\django\db\models\sql\query.py", line 1641, in _add_q
    child_clause, needed_inner = self.build_filter(
                                 ~~~~~~~~~~~~~~~~~^
        child,
        ^^^^^^
    ...<7 lines>...
        update_join_types=update_join_types,
        ^^^^^^^^^^^^^^^^^^^^^^^^^^^^^^^^^^^^
    )
    ^
  File "D:\Project\venv\Lib\site-packages\django\db\models\sql\query.py", line 1491, in build_filter
    lookups, parts, reffed_expression = self.solve_lookup_type(arg, summarize)
                                        ~~~~~~~~~~~~~~~~~~~~~~^^^^^^^^^^^^^^^^
  File "D:\Project\venv\Lib\site-packages\django\db\models\sql\query.py", line 1303, in solve_lookup_type
    _, field, _, lookup_parts = self.names_to_path(lookup_splitted, self.get_meta())
                                ~~~~~~~~~~~~~~~~~~^^^^^^^^^^^^^^^^^^^^^^^^^^^^^^^^^^
  File "D:\Project\venv\Lib\site-packages\django\db\models\sql\query.py", line 1768, in names_to_path
    raise FieldError(
    ...<2 lines>...
    )
django.core.exceptions.FieldError: Cannot resolve keyword 'staffs' into field. Choices are: end_date, id, lesson_start_time, name, start_date, students, teachers
"GET /dashboard/ HTTP/1.1" 500 147212
Internal Server Error: /dashboard/
Traceback (most recent call last):
  File "D:\Project\venv\Lib\site-packages\django\core\handlers\exception.py", line 55, in inner
    response = get_response(request)
  File "D:\Project\venv\Lib\site-packages\django\core\handlers\base.py", line 197, in _get_response
    response = wrapped_callback(request, *callback_args, **callback_kwargs)
  File "D:\Project\venv\Lib\site-packages\django\views\decorators\csrf.py", line 65, in _view_wrapper
    return view_func(request, *args, **kwargs)
  File "D:\Project\venv\Lib\site-packages\django\views\generic\base.py", line 104, in view
    return self.dispatch(request, *args, **kwargs)
           ~~~~~~~~~~~~~^^^^^^^^^^^^^^^^^^^^^^^^^^
  File "D:\Project\venv\Lib\site-packages\rest_framework\views.py", line 515, in dispatch
    response = self.handle_exception(exc)
  File "D:\Project\venv\Lib\site-packages\rest_framework\views.py", line 475, in handle_exception
    self.raise_uncaught_exception(exc)
    ~~~~~~~~~~~~~~~~~~~~~~~~~~~~~^^^^^
  File "D:\Project\venv\Lib\site-packages\rest_framework\views.py", line 486, in raise_uncaught_exception
    raise exc
  File "D:\Project\venv\Lib\site-packages\rest_framework\views.py", line 512, in dispatch
    response = handler(request, *args, **kwargs)
  File "D:\Project\venv\Lib\site-packages\rest_framework\decorators.py", line 50, in handler
    return func(*args, **kwargs)
  File "D:\Project\base\views.py", line 86, in dashboard
    groups = [{"id": group.id, "name": group.name} for group in Group.objects.filter(staffs=user)]
                                                                ~~~~~~~~~~~~~~~~~~~~^^^^^^^^^^^^^
  File "D:\Project\venv\Lib\site-packages\django\db\models\manager.py", line 87, in manager_method
    return getattr(self.get_queryset(), name)(*args, **kwargs)
           ~~~~~~~~~~~~~~~~~~~~~~~~~~~~~~~~~~^^^^^^^^^^^^^^^^^
  File "D:\Project\venv\Lib\site-packages\django\db\models\query.py", line 1476, in filter
    return self._filter_or_exclude(False, args, kwargs)
           ~~~~~~~~~~~~~~~~~~~~~~~^^^^^^^^^^^^^^^^^^^^^
  File "D:\Project\venv\Lib\site-packages\django\db\models\query.py", line 1494, in _filter_or_exclude
    clone._filter_or_exclude_inplace(negate, args, kwargs)
    ~~~~~~~~~~~~~~~~~~~~~~~~~~~~~~~~^^^^^^^^^^^^^^^^^^^^^^
  File "D:\Project\venv\Lib\site-packages\django\db\models\query.py", line 1501, in _filter_or_exclude_inplace
    self._query.add_q(Q(*args, **kwargs))
    ~~~~~~~~~~~~~~~~~^^^^^^^^^^^^^^^^^^^^
  File "D:\Project\venv\Lib\site-packages\django\db\models\sql\query.py", line 1609, in add_q
    clause, _ = self._add_q(q_object, self.used_aliases)
                ~~~~~~~~~~~^^^^^^^^^^^^^^^^^^^^^^^^^^^^^
  File "D:\Project\venv\Lib\site-packages\django\db\models\sql\query.py", line 1641, in _add_q
    child_clause, needed_inner = self.build_filter(
                                 ~~~~~~~~~~~~~~~~~^
        child,
        ^^^^^^
    ...<7 lines>...
        update_join_types=update_join_types,
        ^^^^^^^^^^^^^^^^^^^^^^^^^^^^^^^^^^^^
    )
    ^
  File "D:\Project\venv\Lib\site-packages\django\db\models\sql\query.py", line 1491, in build_filter
    lookups, parts, reffed_expression = self.solve_lookup_type(arg, summarize)
                                        ~~~~~~~~~~~~~~~~~~~~~~^^^^^^^^^^^^^^^^
  File "D:\Project\venv\Lib\site-packages\django\db\models\sql\query.py", line 1303, in solve_lookup_type
    _, field, _, lookup_parts = self.names_to_path(lookup_splitted, self.get_meta())
                                ~~~~~~~~~~~~~~~~~~^^^^^^^^^^^^^^^^^^^^^^^^^^^^^^^^^^
  File "D:\Project\venv\Lib\site-packages\django\db\models\sql\query.py", line 1768, in names_to_path
    raise FieldError(
    ...<2 lines>...
    )
django.core.exceptions.FieldError: Cannot resolve keyword 'staffs' into field. Choices are: end_date, id, lesson_start_time, name, start_date, students, teachers
"GET /dashboard/ HTTP/1.1" 500 147212
Internal Server Error: /dashboard/
Traceback (most recent call last):
  File "D:\Project\venv\Lib\site-packages\django\db\backends\utils.py", line 105, in _execute
    return self.cursor.execute(sql, params)
           ~~~~~~~~~~~~~~~~~~~^^^^^^^^^^^^^
  File "D:\Project\venv\Lib\site-packages\django\db\backends\mysql\base.py", line 76, in execute
    return self.cursor.execute(query, args)
           ~~~~~~~~~~~~~~~~~~~^^^^^^^^^^^^^
  File "D:\Project\venv\Lib\site-packages\MySQLdb\cursors.py", line 179, in execute
    res = self._query(mogrified_query)
  File "D:\Project\venv\Lib\site-packages\MySQLdb\cursors.py", line 330, in _query
    db.query(q)
    ~~~~~~~~^^^
  File "D:\Project\venv\Lib\site-packages\MySQLdb\connections.py", line 280, in query
    _mysql.connection.query(self, query)
    ~~~~~~~~~~~~~~~~~~~~~~~^^^^^^^^^^^^^
MySQLdb.ProgrammingError: (1146, "Table 'demo.base_group_teachers' doesn't exist")

The above exception was the direct cause of the following exception:

Traceback (most recent call last):
  File "D:\Project\venv\Lib\site-packages\django\core\handlers\exception.py", line 55, in inner
    response = get_response(request)
  File "D:\Project\venv\Lib\site-packages\django\core\handlers\base.py", line 197, in _get_response
    response = wrapped_callback(request, *callback_args, **callback_kwargs)
  File "D:\Project\venv\Lib\site-packages\django\views\decorators\csrf.py", line 65, in _view_wrapper
    return view_func(request, *args, **kwargs)
  File "D:\Project\venv\Lib\site-packages\django\views\generic\base.py", line 104, in view
    return self.dispatch(request, *args, **kwargs)
           ~~~~~~~~~~~~~^^^^^^^^^^^^^^^^^^^^^^^^^^
  File "D:\Project\venv\Lib\site-packages\rest_framework\views.py", line 515, in dispatch
    response = self.handle_exception(exc)
  File "D:\Project\venv\Lib\site-packages\rest_framework\views.py", line 475, in handle_exception
    self.raise_uncaught_exception(exc)
    ~~~~~~~~~~~~~~~~~~~~~~~~~~~~~^^^^^
  File "D:\Project\venv\Lib\site-packages\rest_framework\views.py", line 486, in raise_uncaught_exception
    raise exc
  File "D:\Project\venv\Lib\site-packages\rest_framework\views.py", line 512, in dispatch
    response = handler(request, *args, **kwargs)
  File "D:\Project\venv\Lib\site-packages\rest_framework\decorators.py", line 50, in handler
    return func(*args, **kwargs)
  File "D:\Project\base\views.py", line 86, in dashboard
    groups = [{"id": group.id, "name": group.name} for group in Group.objects.filter(teachers__id=user.id)]
                                                                ~~~~~~~~~~~~~~~~~~~~^^^^^^^^^^^^^^^^^^^^^^
  File "D:\Project\venv\Lib\site-packages\django\db\models\query.py", line 400, in __iter__
    self._fetch_all()
    ~~~~~~~~~~~~~~~^^
  File "D:\Project\venv\Lib\site-packages\django\db\models\query.py", line 1928, in _fetch_all
    self._result_cache = list(self._iterable_class(self))
                         ~~~~^^^^^^^^^^^^^^^^^^^^^^^^^^^^
  File "D:\Project\venv\Lib\site-packages\django\db\models\query.py", line 91, in __iter__
    results = compiler.execute_sql(
        chunked_fetch=self.chunked_fetch, chunk_size=self.chunk_size
    )
  File "D:\Project\venv\Lib\site-packages\django\db\models\sql\compiler.py", line 1574, in execute_sql
    cursor.execute(sql, params)
    ~~~~~~~~~~~~~~^^^^^^^^^^^^^
  File "D:\Project\venv\Lib\site-packages\django\db\backends\utils.py", line 122, in execute
    return super().execute(sql, params)
           ~~~~~~~~~~~~~~~^^^^^^^^^^^^^
  File "D:\Project\venv\Lib\site-packages\django\db\backends\utils.py", line 79, in execute
    return self._execute_with_wrappers(
           ~~~~~~~~~~~~~~~~~~~~~~~~~~~^
        sql, params, many=False, executor=self._execute
        ^^^^^^^^^^^^^^^^^^^^^^^^^^^^^^^^^^^^^^^^^^^^^^^
    )
    ^
  File "D:\Project\venv\Lib\site-packages\django\db\backends\utils.py", line 92, in _execute_with_wrappers
    return executor(sql, params, many, context)
  File "D:\Project\venv\Lib\site-packages\django\db\backends\utils.py", line 100, in _execute
    with self.db.wrap_database_errors:
         ^^^^^^^^^^^^^^^^^^^^^^^^^^^^
  File "D:\Project\venv\Lib\site-packages\django\db\utils.py", line 91, in __exit__
    raise dj_exc_value.with_traceback(traceback) from exc_value
  File "D:\Project\venv\Lib\site-packages\django\db\backends\utils.py", line 105, in _execute
    return self.cursor.execute(sql, params)
           ~~~~~~~~~~~~~~~~~~~^^^^^^^^^^^^^
  File "D:\Project\venv\Lib\site-packages\django\db\backends\mysql\base.py", line 76, in execute
    return self.cursor.execute(query, args)
           ~~~~~~~~~~~~~~~~~~~^^^^^^^^^^^^^
  File "D:\Project\venv\Lib\site-packages\MySQLdb\cursors.py", line 179, in execute
    res = self._query(mogrified_query)
  File "D:\Project\venv\Lib\site-packages\MySQLdb\cursors.py", line 330, in _query
    db.query(q)
    ~~~~~~~~^^^
  File "D:\Project\venv\Lib\site-packages\MySQLdb\connections.py", line 280, in query
    _mysql.connection.query(self, query)
    ~~~~~~~~~~~~~~~~~~~~~~~^^^^^^^^^^^^^
django.db.utils.ProgrammingError: (1146, "Table 'demo.base_group_teachers' doesn't exist")
"GET /dashboard/ HTTP/1.1" 500 190171
Internal Server Error: /dashboard/
Traceback (most recent call last):
  File "D:\Project\venv\Lib\site-packages\django\db\backends\utils.py", line 105, in _execute
    return self.cursor.execute(sql, params)
           ~~~~~~~~~~~~~~~~~~~^^^^^^^^^^^^^
  File "D:\Project\venv\Lib\site-packages\django\db\backends\mysql\base.py", line 76, in execute
    return self.cursor.execute(query, args)
           ~~~~~~~~~~~~~~~~~~~^^^^^^^^^^^^^
  File "D:\Project\venv\Lib\site-packages\MySQLdb\cursors.py", line 179, in execute
    res = self._query(mogrified_query)
  File "D:\Project\venv\Lib\site-packages\MySQLdb\cursors.py", line 330, in _query
    db.query(q)
    ~~~~~~~~^^^
  File "D:\Project\venv\Lib\site-packages\MySQLdb\connections.py", line 280, in query
    _mysql.connection.query(self, query)
    ~~~~~~~~~~~~~~~~~~~~~~~^^^^^^^^^^^^^
MySQLdb.ProgrammingError: (1146, "Table 'demo.base_group_teachers' doesn't exist")

The above exception was the direct cause of the following exception:

Traceback (most recent call last):
  File "D:\Project\venv\Lib\site-packages\django\core\handlers\exception.py", line 55, in inner
    response = get_response(request)
  File "D:\Project\venv\Lib\site-packages\django\core\handlers\base.py", line 197, in _get_response
    response = wrapped_callback(request, *callback_args, **callback_kwargs)
  File "D:\Project\venv\Lib\site-packages\django\views\decorators\csrf.py", line 65, in _view_wrapper
    return view_func(request, *args, **kwargs)
  File "D:\Project\venv\Lib\site-packages\django\views\generic\base.py", line 104, in view
    return self.dispatch(request, *args, **kwargs)
           ~~~~~~~~~~~~~^^^^^^^^^^^^^^^^^^^^^^^^^^
  File "D:\Project\venv\Lib\site-packages\rest_framework\views.py", line 515, in dispatch
    response = self.handle_exception(exc)
  File "D:\Project\venv\Lib\site-packages\rest_framework\views.py", line 475, in handle_exception
    self.raise_uncaught_exception(exc)
    ~~~~~~~~~~~~~~~~~~~~~~~~~~~~~^^^^^
  File "D:\Project\venv\Lib\site-packages\rest_framework\views.py", line 486, in raise_uncaught_exception
    raise exc
  File "D:\Project\venv\Lib\site-packages\rest_framework\views.py", line 512, in dispatch
    response = handler(request, *args, **kwargs)
  File "D:\Project\venv\Lib\site-packages\rest_framework\decorators.py", line 50, in handler
    return func(*args, **kwargs)
  File "D:\Project\base\views.py", line 86, in dashboard
    groups = [{"id": group.id, "name": group.name} for group in Group.objects.filter(teachers__id=user.id)]
                                                                ~~~~~~~~~~~~~~~~~~~~^^^^^^^^^^^^^^^^^^^^^^
  File "D:\Project\venv\Lib\site-packages\django\db\models\query.py", line 400, in __iter__
    self._fetch_all()
    ~~~~~~~~~~~~~~~^^
  File "D:\Project\venv\Lib\site-packages\django\db\models\query.py", line 1928, in _fetch_all
    self._result_cache = list(self._iterable_class(self))
                         ~~~~^^^^^^^^^^^^^^^^^^^^^^^^^^^^
  File "D:\Project\venv\Lib\site-packages\django\db\models\query.py", line 91, in __iter__
    results = compiler.execute_sql(
        chunked_fetch=self.chunked_fetch, chunk_size=self.chunk_size
    )
  File "D:\Project\venv\Lib\site-packages\django\db\models\sql\compiler.py", line 1574, in execute_sql
    cursor.execute(sql, params)
    ~~~~~~~~~~~~~~^^^^^^^^^^^^^
  File "D:\Project\venv\Lib\site-packages\django\db\backends\utils.py", line 122, in execute
    return super().execute(sql, params)
           ~~~~~~~~~~~~~~~^^^^^^^^^^^^^
  File "D:\Project\venv\Lib\site-packages\django\db\backends\utils.py", line 79, in execute
    return self._execute_with_wrappers(
           ~~~~~~~~~~~~~~~~~~~~~~~~~~~^
        sql, params, many=False, executor=self._execute
        ^^^^^^^^^^^^^^^^^^^^^^^^^^^^^^^^^^^^^^^^^^^^^^^
    )
    ^
  File "D:\Project\venv\Lib\site-packages\django\db\backends\utils.py", line 92, in _execute_with_wrappers
    return executor(sql, params, many, context)
  File "D:\Project\venv\Lib\site-packages\django\db\backends\utils.py", line 100, in _execute
    with self.db.wrap_database_errors:
         ^^^^^^^^^^^^^^^^^^^^^^^^^^^^
  File "D:\Project\venv\Lib\site-packages\django\db\utils.py", line 91, in __exit__
    raise dj_exc_value.with_traceback(traceback) from exc_value
  File "D:\Project\venv\Lib\site-packages\django\db\backends\utils.py", line 105, in _execute
    return self.cursor.execute(sql, params)
           ~~~~~~~~~~~~~~~~~~~^^^^^^^^^^^^^
  File "D:\Project\venv\Lib\site-packages\django\db\backends\mysql\base.py", line 76, in execute
    return self.cursor.execute(query, args)
           ~~~~~~~~~~~~~~~~~~~^^^^^^^^^^^^^
  File "D:\Project\venv\Lib\site-packages\MySQLdb\cursors.py", line 179, in execute
    res = self._query(mogrified_query)
  File "D:\Project\venv\Lib\site-packages\MySQLdb\cursors.py", line 330, in _query
    db.query(q)
    ~~~~~~~~^^^
  File "D:\Project\venv\Lib\site-packages\MySQLdb\connections.py", line 280, in query
    _mysql.connection.query(self, query)
    ~~~~~~~~~~~~~~~~~~~~~~~^^^^^^^^^^^^^
django.db.utils.ProgrammingError: (1146, "Table 'demo.base_group_teachers' doesn't exist")
"GET /dashboard/ HTTP/1.1" 500 190171
Internal Server Error: /dashboard/
Traceback (most recent call last):
  File "D:\Project\venv\Lib\site-packages\django\db\backends\utils.py", line 105, in _execute
    return self.cursor.execute(sql, params)
           ~~~~~~~~~~~~~~~~~~~^^^^^^^^^^^^^
  File "D:\Project\venv\Lib\site-packages\django\db\backends\mysql\base.py", line 76, in execute
    return self.cursor.execute(query, args)
           ~~~~~~~~~~~~~~~~~~~^^^^^^^^^^^^^
  File "D:\Project\venv\Lib\site-packages\MySQLdb\cursors.py", line 179, in execute
    res = self._query(mogrified_query)
  File "D:\Project\venv\Lib\site-packages\MySQLdb\cursors.py", line 330, in _query
    db.query(q)
    ~~~~~~~~^^^
  File "D:\Project\venv\Lib\site-packages\MySQLdb\connections.py", line 280, in query
    _mysql.connection.query(self, query)
    ~~~~~~~~~~~~~~~~~~~~~~~^^^^^^^^^^^^^
MySQLdb.ProgrammingError: (1146, "Table 'demo.base_group_teachers' doesn't exist")

The above exception was the direct cause of the following exception:

Traceback (most recent call last):
  File "D:\Project\venv\Lib\site-packages\django\core\handlers\exception.py", line 55, in inner
    response = get_response(request)
  File "D:\Project\venv\Lib\site-packages\django\core\handlers\base.py", line 197, in _get_response
    response = wrapped_callback(request, *callback_args, **callback_kwargs)
  File "D:\Project\venv\Lib\site-packages\django\views\decorators\csrf.py", line 65, in _view_wrapper
    return view_func(request, *args, **kwargs)
  File "D:\Project\venv\Lib\site-packages\django\views\generic\base.py", line 104, in view
    return self.dispatch(request, *args, **kwargs)
           ~~~~~~~~~~~~~^^^^^^^^^^^^^^^^^^^^^^^^^^
  File "D:\Project\venv\Lib\site-packages\rest_framework\views.py", line 515, in dispatch
    response = self.handle_exception(exc)
  File "D:\Project\venv\Lib\site-packages\rest_framework\views.py", line 475, in handle_exception
    self.raise_uncaught_exception(exc)
    ~~~~~~~~~~~~~~~~~~~~~~~~~~~~~^^^^^
  File "D:\Project\venv\Lib\site-packages\rest_framework\views.py", line 486, in raise_uncaught_exception
    raise exc
  File "D:\Project\venv\Lib\site-packages\rest_framework\views.py", line 512, in dispatch
    response = handler(request, *args, **kwargs)
  File "D:\Project\venv\Lib\site-packages\rest_framework\decorators.py", line 50, in handler
    return func(*args, **kwargs)
  File "D:\Project\base\views.py", line 86, in dashboard
    groups = [{"id": group.id, "name": group.name} for group in Group.objects.filter(teachers__id=user.id)]
                                                                ~~~~~~~~~~~~~~~~~~~~^^^^^^^^^^^^^^^^^^^^^^
  File "D:\Project\venv\Lib\site-packages\django\db\models\query.py", line 400, in __iter__
    self._fetch_all()
    ~~~~~~~~~~~~~~~^^
  File "D:\Project\venv\Lib\site-packages\django\db\models\query.py", line 1928, in _fetch_all
    self._result_cache = list(self._iterable_class(self))
                         ~~~~^^^^^^^^^^^^^^^^^^^^^^^^^^^^
  File "D:\Project\venv\Lib\site-packages\django\db\models\query.py", line 91, in __iter__
    results = compiler.execute_sql(
        chunked_fetch=self.chunked_fetch, chunk_size=self.chunk_size
    )
  File "D:\Project\venv\Lib\site-packages\django\db\models\sql\compiler.py", line 1574, in execute_sql
    cursor.execute(sql, params)
    ~~~~~~~~~~~~~~^^^^^^^^^^^^^
  File "D:\Project\venv\Lib\site-packages\django\db\backends\utils.py", line 122, in execute
    return super().execute(sql, params)
           ~~~~~~~~~~~~~~~^^^^^^^^^^^^^
  File "D:\Project\venv\Lib\site-packages\django\db\backends\utils.py", line 79, in execute
    return self._execute_with_wrappers(
           ~~~~~~~~~~~~~~~~~~~~~~~~~~~^
        sql, params, many=False, executor=self._execute
        ^^^^^^^^^^^^^^^^^^^^^^^^^^^^^^^^^^^^^^^^^^^^^^^
    )
    ^
  File "D:\Project\venv\Lib\site-packages\django\db\backends\utils.py", line 92, in _execute_with_wrappers
    return executor(sql, params, many, context)
  File "D:\Project\venv\Lib\site-packages\django\db\backends\utils.py", line 100, in _execute
    with self.db.wrap_database_errors:
         ^^^^^^^^^^^^^^^^^^^^^^^^^^^^
  File "D:\Project\venv\Lib\site-packages\django\db\utils.py", line 91, in __exit__
    raise dj_exc_value.with_traceback(traceback) from exc_value
  File "D:\Project\venv\Lib\site-packages\django\db\backends\utils.py", line 105, in _execute
    return self.cursor.execute(sql, params)
           ~~~~~~~~~~~~~~~~~~~^^^^^^^^^^^^^
  File "D:\Project\venv\Lib\site-packages\django\db\backends\mysql\base.py", line 76, in execute
    return self.cursor.execute(query, args)
           ~~~~~~~~~~~~~~~~~~~^^^^^^^^^^^^^
  File "D:\Project\venv\Lib\site-packages\MySQLdb\cursors.py", line 179, in execute
    res = self._query(mogrified_query)
  File "D:\Project\venv\Lib\site-packages\MySQLdb\cursors.py", line 330, in _query
    db.query(q)
    ~~~~~~~~^^^
  File "D:\Project\venv\Lib\site-packages\MySQLdb\connections.py", line 280, in query
    _mysql.connection.query(self, query)
    ~~~~~~~~~~~~~~~~~~~~~~~^^^^^^^^^^^^^
django.db.utils.ProgrammingError: (1146, "Table 'demo.base_group_teachers' doesn't exist")
"GET /dashboard/ HTTP/1.1" 500 190025
Internal Server Error: /dashboard/
Traceback (most recent call last):
  File "D:\Project\venv\Lib\site-packages\django\db\backends\utils.py", line 105, in _execute
    return self.cursor.execute(sql, params)
           ~~~~~~~~~~~~~~~~~~~^^^^^^^^^^^^^
  File "D:\Project\venv\Lib\site-packages\django\db\backends\mysql\base.py", line 76, in execute
    return self.cursor.execute(query, args)
           ~~~~~~~~~~~~~~~~~~~^^^^^^^^^^^^^
  File "D:\Project\venv\Lib\site-packages\MySQLdb\cursors.py", line 179, in execute
    res = self._query(mogrified_query)
  File "D:\Project\venv\Lib\site-packages\MySQLdb\cursors.py", line 330, in _query
    db.query(q)
    ~~~~~~~~^^^
  File "D:\Project\venv\Lib\site-packages\MySQLdb\connections.py", line 280, in query
    _mysql.connection.query(self, query)
    ~~~~~~~~~~~~~~~~~~~~~~~^^^^^^^^^^^^^
MySQLdb.ProgrammingError: (1146, "Table 'demo.base_group_teachers' doesn't exist")

The above exception was the direct cause of the following exception:

Traceback (most recent call last):
  File "D:\Project\venv\Lib\site-packages\django\core\handlers\exception.py", line 55, in inner
    response = get_response(request)
  File "D:\Project\venv\Lib\site-packages\django\core\handlers\base.py", line 197, in _get_response
    response = wrapped_callback(request, *callback_args, **callback_kwargs)
  File "D:\Project\venv\Lib\site-packages\django\views\decorators\csrf.py", line 65, in _view_wrapper
    return view_func(request, *args, **kwargs)
  File "D:\Project\venv\Lib\site-packages\django\views\generic\base.py", line 104, in view
    return self.dispatch(request, *args, **kwargs)
           ~~~~~~~~~~~~~^^^^^^^^^^^^^^^^^^^^^^^^^^
  File "D:\Project\venv\Lib\site-packages\rest_framework\views.py", line 515, in dispatch
    response = self.handle_exception(exc)
  File "D:\Project\venv\Lib\site-packages\rest_framework\views.py", line 475, in handle_exception
    self.raise_uncaught_exception(exc)
    ~~~~~~~~~~~~~~~~~~~~~~~~~~~~~^^^^^
  File "D:\Project\venv\Lib\site-packages\rest_framework\views.py", line 486, in raise_uncaught_exception
    raise exc
  File "D:\Project\venv\Lib\site-packages\rest_framework\views.py", line 512, in dispatch
    response = handler(request, *args, **kwargs)
  File "D:\Project\venv\Lib\site-packages\rest_framework\decorators.py", line 50, in handler
    return func(*args, **kwargs)
  File "D:\Project\base\views.py", line 86, in dashboard
    groups = [{"id": group.id, "name": group.name} for group in Group.objects.filter(teachers__id=user.id)]
                                                                ~~~~~~~~~~~~~~~~~~~~^^^^^^^^^^^^^^^^^^^^^^
  File "D:\Project\venv\Lib\site-packages\django\db\models\query.py", line 400, in __iter__
    self._fetch_all()
    ~~~~~~~~~~~~~~~^^
  File "D:\Project\venv\Lib\site-packages\django\db\models\query.py", line 1928, in _fetch_all
    self._result_cache = list(self._iterable_class(self))
                         ~~~~^^^^^^^^^^^^^^^^^^^^^^^^^^^^
  File "D:\Project\venv\Lib\site-packages\django\db\models\query.py", line 91, in __iter__
    results = compiler.execute_sql(
        chunked_fetch=self.chunked_fetch, chunk_size=self.chunk_size
    )
  File "D:\Project\venv\Lib\site-packages\django\db\models\sql\compiler.py", line 1574, in execute_sql
    cursor.execute(sql, params)
    ~~~~~~~~~~~~~~^^^^^^^^^^^^^
  File "D:\Project\venv\Lib\site-packages\django\db\backends\utils.py", line 122, in execute
    return super().execute(sql, params)
           ~~~~~~~~~~~~~~~^^^^^^^^^^^^^
  File "D:\Project\venv\Lib\site-packages\django\db\backends\utils.py", line 79, in execute
    return self._execute_with_wrappers(
           ~~~~~~~~~~~~~~~~~~~~~~~~~~~^
        sql, params, many=False, executor=self._execute
        ^^^^^^^^^^^^^^^^^^^^^^^^^^^^^^^^^^^^^^^^^^^^^^^
    )
    ^
  File "D:\Project\venv\Lib\site-packages\django\db\backends\utils.py", line 92, in _execute_with_wrappers
    return executor(sql, params, many, context)
  File "D:\Project\venv\Lib\site-packages\django\db\backends\utils.py", line 100, in _execute
    with self.db.wrap_database_errors:
         ^^^^^^^^^^^^^^^^^^^^^^^^^^^^
  File "D:\Project\venv\Lib\site-packages\django\db\utils.py", line 91, in __exit__
    raise dj_exc_value.with_traceback(traceback) from exc_value
  File "D:\Project\venv\Lib\site-packages\django\db\backends\utils.py", line 105, in _execute
    return self.cursor.execute(sql, params)
           ~~~~~~~~~~~~~~~~~~~^^^^^^^^^^^^^
  File "D:\Project\venv\Lib\site-packages\django\db\backends\mysql\base.py", line 76, in execute
    return self.cursor.execute(query, args)
           ~~~~~~~~~~~~~~~~~~~^^^^^^^^^^^^^
  File "D:\Project\venv\Lib\site-packages\MySQLdb\cursors.py", line 179, in execute
    res = self._query(mogrified_query)
  File "D:\Project\venv\Lib\site-packages\MySQLdb\cursors.py", line 330, in _query
    db.query(q)
    ~~~~~~~~^^^
  File "D:\Project\venv\Lib\site-packages\MySQLdb\connections.py", line 280, in query
    _mysql.connection.query(self, query)
    ~~~~~~~~~~~~~~~~~~~~~~~^^^^^^^^^^^^^
django.db.utils.ProgrammingError: (1146, "Table 'demo.base_group_teachers' doesn't exist")
"GET /dashboard/ HTTP/1.1" 500 190025
Internal Server Error: /dashboard/
Traceback (most recent call last):
  File "D:\Project\venv\Lib\site-packages\django\db\backends\utils.py", line 105, in _execute
    return self.cursor.execute(sql, params)
           ~~~~~~~~~~~~~~~~~~~^^^^^^^^^^^^^
  File "D:\Project\venv\Lib\site-packages\django\db\backends\mysql\base.py", line 76, in execute
    return self.cursor.execute(query, args)
           ~~~~~~~~~~~~~~~~~~~^^^^^^^^^^^^^
  File "D:\Project\venv\Lib\site-packages\MySQLdb\cursors.py", line 179, in execute
    res = self._query(mogrified_query)
  File "D:\Project\venv\Lib\site-packages\MySQLdb\cursors.py", line 330, in _query
    db.query(q)
    ~~~~~~~~^^^
  File "D:\Project\venv\Lib\site-packages\MySQLdb\connections.py", line 280, in query
    _mysql.connection.query(self, query)
    ~~~~~~~~~~~~~~~~~~~~~~~^^^^^^^^^^^^^
MySQLdb.ProgrammingError: (1146, "Table 'demo.base_group_teachers' doesn't exist")

The above exception was the direct cause of the following exception:

Traceback (most recent call last):
  File "D:\Project\venv\Lib\site-packages\django\core\handlers\exception.py", line 55, in inner
    response = get_response(request)
  File "D:\Project\venv\Lib\site-packages\django\core\handlers\base.py", line 197, in _get_response
    response = wrapped_callback(request, *callback_args, **callback_kwargs)
  File "D:\Project\venv\Lib\site-packages\django\views\decorators\csrf.py", line 65, in _view_wrapper
    return view_func(request, *args, **kwargs)
  File "D:\Project\venv\Lib\site-packages\django\views\generic\base.py", line 104, in view
    return self.dispatch(request, *args, **kwargs)
           ~~~~~~~~~~~~~^^^^^^^^^^^^^^^^^^^^^^^^^^
  File "D:\Project\venv\Lib\site-packages\rest_framework\views.py", line 515, in dispatch
    response = self.handle_exception(exc)
  File "D:\Project\venv\Lib\site-packages\rest_framework\views.py", line 475, in handle_exception
    self.raise_uncaught_exception(exc)
    ~~~~~~~~~~~~~~~~~~~~~~~~~~~~~^^^^^
  File "D:\Project\venv\Lib\site-packages\rest_framework\views.py", line 486, in raise_uncaught_exception
    raise exc
  File "D:\Project\venv\Lib\site-packages\rest_framework\views.py", line 512, in dispatch
    response = handler(request, *args, **kwargs)
  File "D:\Project\venv\Lib\site-packages\rest_framework\decorators.py", line 50, in handler
    return func(*args, **kwargs)
  File "D:\Project\base\views.py", line 86, in dashboard
    groups = [{"id": group.id, "name": group.name} for group in Group.objects.filter(teachers__id=user.id)]
                                                                ~~~~~~~~~~~~~~~~~~~~^^^^^^^^^^^^^^^^^^^^^^
  File "D:\Project\venv\Lib\site-packages\django\db\models\query.py", line 400, in __iter__
    self._fetch_all()
    ~~~~~~~~~~~~~~~^^
  File "D:\Project\venv\Lib\site-packages\django\db\models\query.py", line 1928, in _fetch_all
    self._result_cache = list(self._iterable_class(self))
                         ~~~~^^^^^^^^^^^^^^^^^^^^^^^^^^^^
  File "D:\Project\venv\Lib\site-packages\django\db\models\query.py", line 91, in __iter__
    results = compiler.execute_sql(
        chunked_fetch=self.chunked_fetch, chunk_size=self.chunk_size
    )
  File "D:\Project\venv\Lib\site-packages\django\db\models\sql\compiler.py", line 1574, in execute_sql
    cursor.execute(sql, params)
    ~~~~~~~~~~~~~~^^^^^^^^^^^^^
  File "D:\Project\venv\Lib\site-packages\django\db\backends\utils.py", line 122, in execute
    return super().execute(sql, params)
           ~~~~~~~~~~~~~~~^^^^^^^^^^^^^
  File "D:\Project\venv\Lib\site-packages\django\db\backends\utils.py", line 79, in execute
    return self._execute_with_wrappers(
           ~~~~~~~~~~~~~~~~~~~~~~~~~~~^
        sql, params, many=False, executor=self._execute
        ^^^^^^^^^^^^^^^^^^^^^^^^^^^^^^^^^^^^^^^^^^^^^^^
    )
    ^
  File "D:\Project\venv\Lib\site-packages\django\db\backends\utils.py", line 92, in _execute_with_wrappers
    return executor(sql, params, many, context)
  File "D:\Project\venv\Lib\site-packages\django\db\backends\utils.py", line 100, in _execute
    with self.db.wrap_database_errors:
         ^^^^^^^^^^^^^^^^^^^^^^^^^^^^
  File "D:\Project\venv\Lib\site-packages\django\db\utils.py", line 91, in __exit__
    raise dj_exc_value.with_traceback(traceback) from exc_value
  File "D:\Project\venv\Lib\site-packages\django\db\backends\utils.py", line 105, in _execute
    return self.cursor.execute(sql, params)
           ~~~~~~~~~~~~~~~~~~~^^^^^^^^^^^^^
  File "D:\Project\venv\Lib\site-packages\django\db\backends\mysql\base.py", line 76, in execute
    return self.cursor.execute(query, args)
           ~~~~~~~~~~~~~~~~~~~^^^^^^^^^^^^^
  File "D:\Project\venv\Lib\site-packages\MySQLdb\cursors.py", line 179, in execute
    res = self._query(mogrified_query)
  File "D:\Project\venv\Lib\site-packages\MySQLdb\cursors.py", line 330, in _query
    db.query(q)
    ~~~~~~~~^^^
  File "D:\Project\venv\Lib\site-packages\MySQLdb\connections.py", line 280, in query
    _mysql.connection.query(self, query)
    ~~~~~~~~~~~~~~~~~~~~~~~^^^^^^^^^^^^^
django.db.utils.ProgrammingError: (1146, "Table 'demo.base_group_teachers' doesn't exist")
"GET /dashboard/ HTTP/1.1" 500 190025
Internal Server Error: /dashboard/
Traceback (most recent call last):
  File "D:\Project\venv\Lib\site-packages\django\db\backends\utils.py", line 105, in _execute
    return self.cursor.execute(sql, params)
           ~~~~~~~~~~~~~~~~~~~^^^^^^^^^^^^^
  File "D:\Project\venv\Lib\site-packages\django\db\backends\mysql\base.py", line 76, in execute
    return self.cursor.execute(query, args)
           ~~~~~~~~~~~~~~~~~~~^^^^^^^^^^^^^
  File "D:\Project\venv\Lib\site-packages\MySQLdb\cursors.py", line 179, in execute
    res = self._query(mogrified_query)
  File "D:\Project\venv\Lib\site-packages\MySQLdb\cursors.py", line 330, in _query
    db.query(q)
    ~~~~~~~~^^^
  File "D:\Project\venv\Lib\site-packages\MySQLdb\connections.py", line 280, in query
    _mysql.connection.query(self, query)
    ~~~~~~~~~~~~~~~~~~~~~~~^^^^^^^^^^^^^
MySQLdb.ProgrammingError: (1146, "Table 'demo.base_group_teachers' doesn't exist")

The above exception was the direct cause of the following exception:

Traceback (most recent call last):
  File "D:\Project\venv\Lib\site-packages\django\core\handlers\exception.py", line 55, in inner
    response = get_response(request)
  File "D:\Project\venv\Lib\site-packages\django\core\handlers\base.py", line 197, in _get_response
    response = wrapped_callback(request, *callback_args, **callback_kwargs)
  File "D:\Project\venv\Lib\site-packages\django\views\decorators\csrf.py", line 65, in _view_wrapper
    return view_func(request, *args, **kwargs)
  File "D:\Project\venv\Lib\site-packages\django\views\generic\base.py", line 104, in view
    return self.dispatch(request, *args, **kwargs)
           ~~~~~~~~~~~~~^^^^^^^^^^^^^^^^^^^^^^^^^^
  File "D:\Project\venv\Lib\site-packages\rest_framework\views.py", line 515, in dispatch
    response = self.handle_exception(exc)
  File "D:\Project\venv\Lib\site-packages\rest_framework\views.py", line 475, in handle_exception
    self.raise_uncaught_exception(exc)
    ~~~~~~~~~~~~~~~~~~~~~~~~~~~~~^^^^^
  File "D:\Project\venv\Lib\site-packages\rest_framework\views.py", line 486, in raise_uncaught_exception
    raise exc
  File "D:\Project\venv\Lib\site-packages\rest_framework\views.py", line 512, in dispatch
    response = handler(request, *args, **kwargs)
  File "D:\Project\venv\Lib\site-packages\rest_framework\decorators.py", line 50, in handler
    return func(*args, **kwargs)
  File "D:\Project\base\views.py", line 86, in dashboard
    groups = [{"id": group.id, "name": group.name} for group in Group.objects.filter(teachers__id=user.id)]
                                                                ~~~~~~~~~~~~~~~~~~~~^^^^^^^^^^^^^^^^^^^^^^
  File "D:\Project\venv\Lib\site-packages\django\db\models\query.py", line 400, in __iter__
    self._fetch_all()
    ~~~~~~~~~~~~~~~^^
  File "D:\Project\venv\Lib\site-packages\django\db\models\query.py", line 1928, in _fetch_all
    self._result_cache = list(self._iterable_class(self))
                         ~~~~^^^^^^^^^^^^^^^^^^^^^^^^^^^^
  File "D:\Project\venv\Lib\site-packages\django\db\models\query.py", line 91, in __iter__
    results = compiler.execute_sql(
        chunked_fetch=self.chunked_fetch, chunk_size=self.chunk_size
    )
  File "D:\Project\venv\Lib\site-packages\django\db\models\sql\compiler.py", line 1574, in execute_sql
    cursor.execute(sql, params)
    ~~~~~~~~~~~~~~^^^^^^^^^^^^^
  File "D:\Project\venv\Lib\site-packages\django\db\backends\utils.py", line 122, in execute
    return super().execute(sql, params)
           ~~~~~~~~~~~~~~~^^^^^^^^^^^^^
  File "D:\Project\venv\Lib\site-packages\django\db\backends\utils.py", line 79, in execute
    return self._execute_with_wrappers(
           ~~~~~~~~~~~~~~~~~~~~~~~~~~~^
        sql, params, many=False, executor=self._execute
        ^^^^^^^^^^^^^^^^^^^^^^^^^^^^^^^^^^^^^^^^^^^^^^^
    )
    ^
  File "D:\Project\venv\Lib\site-packages\django\db\backends\utils.py", line 92, in _execute_with_wrappers
    return executor(sql, params, many, context)
  File "D:\Project\venv\Lib\site-packages\django\db\backends\utils.py", line 100, in _execute
    with self.db.wrap_database_errors:
         ^^^^^^^^^^^^^^^^^^^^^^^^^^^^
  File "D:\Project\venv\Lib\site-packages\django\db\utils.py", line 91, in __exit__
    raise dj_exc_value.with_traceback(traceback) from exc_value
  File "D:\Project\venv\Lib\site-packages\django\db\backends\utils.py", line 105, in _execute
    return self.cursor.execute(sql, params)
           ~~~~~~~~~~~~~~~~~~~^^^^^^^^^^^^^
  File "D:\Project\venv\Lib\site-packages\django\db\backends\mysql\base.py", line 76, in execute
    return self.cursor.execute(query, args)
           ~~~~~~~~~~~~~~~~~~~^^^^^^^^^^^^^
  File "D:\Project\venv\Lib\site-packages\MySQLdb\cursors.py", line 179, in execute
    res = self._query(mogrified_query)
  File "D:\Project\venv\Lib\site-packages\MySQLdb\cursors.py", line 330, in _query
    db.query(q)
    ~~~~~~~~^^^
  File "D:\Project\venv\Lib\site-packages\MySQLdb\connections.py", line 280, in query
    _mysql.connection.query(self, query)
    ~~~~~~~~~~~~~~~~~~~~~~~^^^^^^^^^^^^^
django.db.utils.ProgrammingError: (1146, "Table 'demo.base_group_teachers' doesn't exist")
"GET /dashboard/ HTTP/1.1" 500 190025
Internal Server Error: /dashboard/
Traceback (most recent call last):
  File "D:\Project\venv\Lib\site-packages\django\core\handlers\exception.py", line 55, in inner
    response = get_response(request)
  File "D:\Project\venv\Lib\site-packages\django\core\handlers\base.py", line 197, in _get_response
    response = wrapped_callback(request, *callback_args, **callback_kwargs)
  File "D:\Project\venv\Lib\site-packages\django\views\decorators\csrf.py", line 65, in _view_wrapper
    return view_func(request, *args, **kwargs)
  File "D:\Project\venv\Lib\site-packages\django\views\generic\base.py", line 104, in view
    return self.dispatch(request, *args, **kwargs)
           ~~~~~~~~~~~~~^^^^^^^^^^^^^^^^^^^^^^^^^^
  File "D:\Project\venv\Lib\site-packages\rest_framework\views.py", line 515, in dispatch
    response = self.handle_exception(exc)
  File "D:\Project\venv\Lib\site-packages\rest_framework\views.py", line 475, in handle_exception
    self.raise_uncaught_exception(exc)
    ~~~~~~~~~~~~~~~~~~~~~~~~~~~~~^^^^^
  File "D:\Project\venv\Lib\site-packages\rest_framework\views.py", line 486, in raise_uncaught_exception
    raise exc
  File "D:\Project\venv\Lib\site-packages\rest_framework\views.py", line 512, in dispatch
    response = handler(request, *args, **kwargs)
  File "D:\Project\venv\Lib\site-packages\rest_framework\decorators.py", line 50, in handler
    return func(*args, **kwargs)
  File "D:\Project\base\views.py", line 86, in dashboard
    groups = [{"id": group.id, "name": group.name} for group in Group.objects.filter(teacher__id=user.id)]
                                                                ~~~~~~~~~~~~~~~~~~~~^^^^^^^^^^^^^^^^^^^^^
  File "D:\Project\venv\Lib\site-packages\django\db\models\manager.py", line 87, in manager_method
    return getattr(self.get_queryset(), name)(*args, **kwargs)
           ~~~~~~~~~~~~~~~~~~~~~~~~~~~~~~~~~~^^^^^^^^^^^^^^^^^
  File "D:\Project\venv\Lib\site-packages\django\db\models\query.py", line 1476, in filter
    return self._filter_or_exclude(False, args, kwargs)
           ~~~~~~~~~~~~~~~~~~~~~~~^^^^^^^^^^^^^^^^^^^^^
  File "D:\Project\venv\Lib\site-packages\django\db\models\query.py", line 1494, in _filter_or_exclude
    clone._filter_or_exclude_inplace(negate, args, kwargs)
    ~~~~~~~~~~~~~~~~~~~~~~~~~~~~~~~~^^^^^^^^^^^^^^^^^^^^^^
  File "D:\Project\venv\Lib\site-packages\django\db\models\query.py", line 1501, in _filter_or_exclude_inplace
    self._query.add_q(Q(*args, **kwargs))
    ~~~~~~~~~~~~~~~~~^^^^^^^^^^^^^^^^^^^^
  File "D:\Project\venv\Lib\site-packages\django\db\models\sql\query.py", line 1609, in add_q
    clause, _ = self._add_q(q_object, self.used_aliases)
                ~~~~~~~~~~~^^^^^^^^^^^^^^^^^^^^^^^^^^^^^
  File "D:\Project\venv\Lib\site-packages\django\db\models\sql\query.py", line 1641, in _add_q
    child_clause, needed_inner = self.build_filter(
                                 ~~~~~~~~~~~~~~~~~^
        child,
        ^^^^^^
    ...<7 lines>...
        update_join_types=update_join_types,
        ^^^^^^^^^^^^^^^^^^^^^^^^^^^^^^^^^^^^
    )
    ^
  File "D:\Project\venv\Lib\site-packages\django\db\models\sql\query.py", line 1491, in build_filter
    lookups, parts, reffed_expression = self.solve_lookup_type(arg, summarize)
                                        ~~~~~~~~~~~~~~~~~~~~~~^^^^^^^^^^^^^^^^
  File "D:\Project\venv\Lib\site-packages\django\db\models\sql\query.py", line 1303, in solve_lookup_type
    _, field, _, lookup_parts = self.names_to_path(lookup_splitted, self.get_meta())
                                ~~~~~~~~~~~~~~~~~~^^^^^^^^^^^^^^^^^^^^^^^^^^^^^^^^^^
  File "D:\Project\venv\Lib\site-packages\django\db\models\sql\query.py", line 1768, in names_to_path
    raise FieldError(
    ...<2 lines>...
    )
django.core.exceptions.FieldError: Cannot resolve keyword 'teacher' into field. Choices are: end_date, id, lesson_start_time, name, start_date, students, teachers
"GET /dashboard/ HTTP/1.1" 500 146929
Internal Server Error: /dashboard/
Traceback (most recent call last):
  File "D:\Project\venv\Lib\site-packages\django\db\backends\utils.py", line 105, in _execute
    return self.cursor.execute(sql, params)
           ~~~~~~~~~~~~~~~~~~~^^^^^^^^^^^^^
  File "D:\Project\venv\Lib\site-packages\django\db\backends\mysql\base.py", line 76, in execute
    return self.cursor.execute(query, args)
           ~~~~~~~~~~~~~~~~~~~^^^^^^^^^^^^^
  File "D:\Project\venv\Lib\site-packages\MySQLdb\cursors.py", line 179, in execute
    res = self._query(mogrified_query)
  File "D:\Project\venv\Lib\site-packages\MySQLdb\cursors.py", line 330, in _query
    db.query(q)
    ~~~~~~~~^^^
  File "D:\Project\venv\Lib\site-packages\MySQLdb\connections.py", line 280, in query
    _mysql.connection.query(self, query)
    ~~~~~~~~~~~~~~~~~~~~~~~^^^^^^^^^^^^^
MySQLdb.ProgrammingError: (1146, "Table 'demo.base_group_teachers' doesn't exist")

The above exception was the direct cause of the following exception:

Traceback (most recent call last):
  File "D:\Project\venv\Lib\site-packages\django\core\handlers\exception.py", line 55, in inner
    response = get_response(request)
  File "D:\Project\venv\Lib\site-packages\django\core\handlers\base.py", line 197, in _get_response
    response = wrapped_callback(request, *callback_args, **callback_kwargs)
  File "D:\Project\venv\Lib\site-packages\django\views\decorators\csrf.py", line 65, in _view_wrapper
    return view_func(request, *args, **kwargs)
  File "D:\Project\venv\Lib\site-packages\django\views\generic\base.py", line 104, in view
    return self.dispatch(request, *args, **kwargs)
           ~~~~~~~~~~~~~^^^^^^^^^^^^^^^^^^^^^^^^^^
  File "D:\Project\venv\Lib\site-packages\rest_framework\views.py", line 515, in dispatch
    response = self.handle_exception(exc)
  File "D:\Project\venv\Lib\site-packages\rest_framework\views.py", line 475, in handle_exception
    self.raise_uncaught_exception(exc)
    ~~~~~~~~~~~~~~~~~~~~~~~~~~~~~^^^^^
  File "D:\Project\venv\Lib\site-packages\rest_framework\views.py", line 486, in raise_uncaught_exception
    raise exc
  File "D:\Project\venv\Lib\site-packages\rest_framework\views.py", line 512, in dispatch
    response = handler(request, *args, **kwargs)
  File "D:\Project\venv\Lib\site-packages\rest_framework\decorators.py", line 50, in handler
    return func(*args, **kwargs)
  File "D:\Project\base\views.py", line 86, in dashboard
    groups = [{"id": group.id, "name": group.name} for group in Group.objects.filter(teachers=user)]
                                                                ~~~~~~~~~~~~~~~~~~~~^^^^^^^^^^^^^^^
  File "D:\Project\venv\Lib\site-packages\django\db\models\query.py", line 400, in __iter__
    self._fetch_all()
    ~~~~~~~~~~~~~~~^^
  File "D:\Project\venv\Lib\site-packages\django\db\models\query.py", line 1928, in _fetch_all
    self._result_cache = list(self._iterable_class(self))
                         ~~~~^^^^^^^^^^^^^^^^^^^^^^^^^^^^
  File "D:\Project\venv\Lib\site-packages\django\db\models\query.py", line 91, in __iter__
    results = compiler.execute_sql(
        chunked_fetch=self.chunked_fetch, chunk_size=self.chunk_size
    )
  File "D:\Project\venv\Lib\site-packages\django\db\models\sql\compiler.py", line 1574, in execute_sql
    cursor.execute(sql, params)
    ~~~~~~~~~~~~~~^^^^^^^^^^^^^
  File "D:\Project\venv\Lib\site-packages\django\db\backends\utils.py", line 122, in execute
    return super().execute(sql, params)
           ~~~~~~~~~~~~~~~^^^^^^^^^^^^^
  File "D:\Project\venv\Lib\site-packages\django\db\backends\utils.py", line 79, in execute
    return self._execute_with_wrappers(
           ~~~~~~~~~~~~~~~~~~~~~~~~~~~^
        sql, params, many=False, executor=self._execute
        ^^^^^^^^^^^^^^^^^^^^^^^^^^^^^^^^^^^^^^^^^^^^^^^
    )
    ^
  File "D:\Project\venv\Lib\site-packages\django\db\backends\utils.py", line 92, in _execute_with_wrappers
    return executor(sql, params, many, context)
  File "D:\Project\venv\Lib\site-packages\django\db\backends\utils.py", line 100, in _execute
    with self.db.wrap_database_errors:
         ^^^^^^^^^^^^^^^^^^^^^^^^^^^^
  File "D:\Project\venv\Lib\site-packages\django\db\utils.py", line 91, in __exit__
    raise dj_exc_value.with_traceback(traceback) from exc_value
  File "D:\Project\venv\Lib\site-packages\django\db\backends\utils.py", line 105, in _execute
    return self.cursor.execute(sql, params)
           ~~~~~~~~~~~~~~~~~~~^^^^^^^^^^^^^
  File "D:\Project\venv\Lib\site-packages\django\db\backends\mysql\base.py", line 76, in execute
    return self.cursor.execute(query, args)
           ~~~~~~~~~~~~~~~~~~~^^^^^^^^^^^^^
  File "D:\Project\venv\Lib\site-packages\MySQLdb\cursors.py", line 179, in execute
    res = self._query(mogrified_query)
  File "D:\Project\venv\Lib\site-packages\MySQLdb\cursors.py", line 330, in _query
    db.query(q)
    ~~~~~~~~^^^
  File "D:\Project\venv\Lib\site-packages\MySQLdb\connections.py", line 280, in query
    _mysql.connection.query(self, query)
    ~~~~~~~~~~~~~~~~~~~~~~~^^^^^^^^^^^^^
django.db.utils.ProgrammingError: (1146, "Table 'demo.base_group_teachers' doesn't exist")
"GET /dashboard/ HTTP/1.1" 500 189997
Internal Server Error: /dashboard/
Traceback (most recent call last):
  File "D:\Project\venv\Lib\site-packages\django\core\handlers\exception.py", line 55, in inner
    response = get_response(request)
  File "D:\Project\venv\Lib\site-packages\django\core\handlers\base.py", line 197, in _get_response
    response = wrapped_callback(request, *callback_args, **callback_kwargs)
  File "D:\Project\venv\Lib\site-packages\django\views\decorators\csrf.py", line 65, in _view_wrapper
    return view_func(request, *args, **kwargs)
  File "D:\Project\venv\Lib\site-packages\django\views\generic\base.py", line 104, in view
    return self.dispatch(request, *args, **kwargs)
           ~~~~~~~~~~~~~^^^^^^^^^^^^^^^^^^^^^^^^^^
  File "D:\Project\venv\Lib\site-packages\rest_framework\views.py", line 515, in dispatch
    response = self.handle_exception(exc)
  File "D:\Project\venv\Lib\site-packages\rest_framework\views.py", line 475, in handle_exception
    self.raise_uncaught_exception(exc)
    ~~~~~~~~~~~~~~~~~~~~~~~~~~~~~^^^^^
  File "D:\Project\venv\Lib\site-packages\rest_framework\views.py", line 486, in raise_uncaught_exception
    raise exc
  File "D:\Project\venv\Lib\site-packages\rest_framework\views.py", line 512, in dispatch
    response = handler(request, *args, **kwargs)
  File "D:\Project\venv\Lib\site-packages\rest_framework\decorators.py", line 50, in handler
    return func(*args, **kwargs)
  File "D:\Project\base\views.py", line 86, in dashboard
    groups = [{"id": group.id, "name": group.name} for group in Group.objects.filter(teachers=user)]
                                                                ~~~~~~~~~~~~~~~~~~~~^^^^^^^^^^^^^^^
  File "D:\Project\venv\Lib\site-packages\django\db\models\manager.py", line 87, in manager_method
    return getattr(self.get_queryset(), name)(*args, **kwargs)
           ~~~~~~~~~~~~~~~~~~~~~~~~~~~~~~~~~~^^^^^^^^^^^^^^^^^
  File "D:\Project\venv\Lib\site-packages\django\db\models\query.py", line 1476, in filter
    return self._filter_or_exclude(False, args, kwargs)
           ~~~~~~~~~~~~~~~~~~~~~~~^^^^^^^^^^^^^^^^^^^^^
  File "D:\Project\venv\Lib\site-packages\django\db\models\query.py", line 1494, in _filter_or_exclude
    clone._filter_or_exclude_inplace(negate, args, kwargs)
    ~~~~~~~~~~~~~~~~~~~~~~~~~~~~~~~~^^^^^^^^^^^^^^^^^^^^^^
  File "D:\Project\venv\Lib\site-packages\django\db\models\query.py", line 1501, in _filter_or_exclude_inplace
    self._query.add_q(Q(*args, **kwargs))
    ~~~~~~~~~~~~~~~~~^^^^^^^^^^^^^^^^^^^^
  File "D:\Project\venv\Lib\site-packages\django\db\models\sql\query.py", line 1609, in add_q
    clause, _ = self._add_q(q_object, self.used_aliases)
                ~~~~~~~~~~~^^^^^^^^^^^^^^^^^^^^^^^^^^^^^
  File "D:\Project\venv\Lib\site-packages\django\db\models\sql\query.py", line 1641, in _add_q
    child_clause, needed_inner = self.build_filter(
                                 ~~~~~~~~~~~~~~~~~^
        child,
        ^^^^^^
    ...<7 lines>...
        update_join_types=update_join_types,
        ^^^^^^^^^^^^^^^^^^^^^^^^^^^^^^^^^^^^
    )
    ^
  File "D:\Project\venv\Lib\site-packages\django\db\models\sql\query.py", line 1491, in build_filter
    lookups, parts, reffed_expression = self.solve_lookup_type(arg, summarize)
                                        ~~~~~~~~~~~~~~~~~~~~~~^^^^^^^^^^^^^^^^
  File "D:\Project\venv\Lib\site-packages\django\db\models\sql\query.py", line 1303, in solve_lookup_type
    _, field, _, lookup_parts = self.names_to_path(lookup_splitted, self.get_meta())
                                ~~~~~~~~~~~~~~~~~~^^^^^^^^^^^^^^^^^^^^^^^^^^^^^^^^^^
  File "D:\Project\venv\Lib\site-packages\django\db\models\sql\query.py", line 1768, in names_to_path
    raise FieldError(
    ...<2 lines>...
    )
django.core.exceptions.FieldError: Cannot resolve keyword 'teachers' into field. Choices are: end_date, id, lesson_start_time, name, start_date, students, teacher, teacher_id
"GET /dashboard/ HTTP/1.1" 500 147204
Internal Server Error: /group/2/
Traceback (most recent call last):
  File "D:\Project\venv\Lib\site-packages\django\core\handlers\exception.py", line 55, in inner
    response = get_response(request)
  File "D:\Project\venv\Lib\site-packages\django\core\handlers\base.py", line 197, in _get_response
    response = wrapped_callback(request, *callback_args, **callback_kwargs)
  File "D:\Project\venv\Lib\site-packages\django\views\decorators\csrf.py", line 65, in _view_wrapper
    return view_func(request, *args, **kwargs)
  File "D:\Project\venv\Lib\site-packages\django\views\generic\base.py", line 104, in view
    return self.dispatch(request, *args, **kwargs)
           ~~~~~~~~~~~~~^^^^^^^^^^^^^^^^^^^^^^^^^^
  File "D:\Project\venv\Lib\site-packages\rest_framework\views.py", line 515, in dispatch
    response = self.handle_exception(exc)
  File "D:\Project\venv\Lib\site-packages\rest_framework\views.py", line 475, in handle_exception
    self.raise_uncaught_exception(exc)
    ~~~~~~~~~~~~~~~~~~~~~~~~~~~~~^^^^^
  File "D:\Project\venv\Lib\site-packages\rest_framework\views.py", line 486, in raise_uncaught_exception
    raise exc
  File "D:\Project\venv\Lib\site-packages\rest_framework\views.py", line 512, in dispatch
    response = handler(request, *args, **kwargs)
  File "D:\Project\venv\Lib\site-packages\rest_framework\decorators.py", line 50, in handler
    return func(*args, **kwargs)
  File "D:\Project\base\views.py", line 109, in group_details
    for student in group.student_set.all()
                   ^^^^^^^^^^^^^^^^^
AttributeError: 'Group' object has no attribute 'student_set'. Did you mean: 'students'?
"GET /group/2/ HTTP/1.1" 500 102866
Internal Server Error: /admin_settings_page/base/group/
Traceback (most recent call last):
  File "D:\Project\venv\Lib\site-packages\django\db\models\options.py", line 676, in get_field
    return self.fields_map[field_name]
           ~~~~~~~~~~~~~~~^^^^^^^^^^^^
KeyError: 'teachers_display'

During handling of the above exception, another exception occurred:

Traceback (most recent call last):
  File "D:\Project\venv\Lib\site-packages\django\contrib\admin\utils.py", line 290, in lookup_field
    f = _get_non_gfk_field(opts, name)
  File "D:\Project\venv\Lib\site-packages\django\contrib\admin\utils.py", line 330, in _get_non_gfk_field
    field = opts.get_field(name)
  File "D:\Project\venv\Lib\site-packages\django\db\models\options.py", line 678, in get_field
    raise FieldDoesNotExist(
        "%s has no field named '%s'" % (self.object_name, field_name)
    )
django.core.exceptions.FieldDoesNotExist: Group has no field named 'teachers_display'

During handling of the above exception, another exception occurred:

Traceback (most recent call last):
  File "D:\Project\venv\Lib\site-packages\django\core\handlers\exception.py", line 55, in inner
    response = get_response(request)
  File "D:\Project\venv\Lib\site-packages\django\core\handlers\base.py", line 220, in _get_response
    response = response.render()
  File "D:\Project\venv\Lib\site-packages\django\template\response.py", line 114, in render
    self.content = self.rendered_content
                   ^^^^^^^^^^^^^^^^^^^^^
  File "D:\Project\venv\Lib\site-packages\django\template\response.py", line 92, in rendered_content
    return template.render(context, self._request)
           ~~~~~~~~~~~~~~~^^^^^^^^^^^^^^^^^^^^^^^^
  File "D:\Project\venv\Lib\site-packages\django\template\backends\django.py", line 107, in render
    return self.template.render(context)
           ~~~~~~~~~~~~~~~~~~~~^^^^^^^^^
  File "D:\Project\venv\Lib\site-packages\django\template\base.py", line 171, in render
    return self._render(context)
           ~~~~~~~~~~~~^^^^^^^^^
  File "D:\Project\venv\Lib\site-packages\django\template\base.py", line 163, in _render
    return self.nodelist.render(context)
           ~~~~~~~~~~~~~~~~~~~~^^^^^^^^^
  File "D:\Project\venv\Lib\site-packages\django\template\base.py", line 1008, in render
    return SafeString("".join([node.render_annotated(context) for node in self]))
                               ~~~~~~~~~~~~~~~~~~~~~^^^^^^^^^
  File "D:\Project\venv\Lib\site-packages\django\template\base.py", line 969, in render_annotated
    return self.render(context)
           ~~~~~~~~~~~^^^^^^^^^
  File "D:\Project\venv\Lib\site-packages\django\template\loader_tags.py", line 159, in render
    return compiled_parent._render(context)
           ~~~~~~~~~~~~~~~~~~~~~~~^^^^^^^^^
  File "D:\Project\venv\Lib\site-packages\django\template\base.py", line 163, in _render
    return self.nodelist.render(context)
           ~~~~~~~~~~~~~~~~~~~~^^^^^^^^^
  File "D:\Project\venv\Lib\site-packages\django\template\base.py", line 1008, in render
    return SafeString("".join([node.render_annotated(context) for node in self]))
                               ~~~~~~~~~~~~~~~~~~~~~^^^^^^^^^
  File "D:\Project\venv\Lib\site-packages\django\template\base.py", line 969, in render_annotated
    return self.render(context)
           ~~~~~~~~~~~^^^^^^^^^
  File "D:\Project\venv\Lib\site-packages\django\template\loader_tags.py", line 159, in render
    return compiled_parent._render(context)
           ~~~~~~~~~~~~~~~~~~~~~~~^^^^^^^^^
  File "D:\Project\venv\Lib\site-packages\django\template\base.py", line 163, in _render
    return self.nodelist.render(context)
           ~~~~~~~~~~~~~~~~~~~~^^^^^^^^^
  File "D:\Project\venv\Lib\site-packages\django\template\base.py", line 1008, in render
    return SafeString("".join([node.render_annotated(context) for node in self]))
                               ~~~~~~~~~~~~~~~~~~~~~^^^^^^^^^
  File "D:\Project\venv\Lib\site-packages\django\template\base.py", line 969, in render_annotated
    return self.render(context)
           ~~~~~~~~~~~^^^^^^^^^
  File "D:\Project\venv\Lib\site-packages\django\template\loader_tags.py", line 159, in render
    return compiled_parent._render(context)
           ~~~~~~~~~~~~~~~~~~~~~~~^^^^^^^^^
  File "D:\Project\venv\Lib\site-packages\django\template\base.py", line 163, in _render
    return self.nodelist.render(context)
           ~~~~~~~~~~~~~~~~~~~~^^^^^^^^^
  File "D:\Project\venv\Lib\site-packages\django\template\base.py", line 1008, in render
    return SafeString("".join([node.render_annotated(context) for node in self]))
                               ~~~~~~~~~~~~~~~~~~~~~^^^^^^^^^
  File "D:\Project\venv\Lib\site-packages\django\template\base.py", line 969, in render_annotated
    return self.render(context)
           ~~~~~~~~~~~^^^^^^^^^
  File "D:\Project\venv\Lib\site-packages\django\template\loader_tags.py", line 159, in render
    return compiled_parent._render(context)
           ~~~~~~~~~~~~~~~~~~~~~~~^^^^^^^^^
  File "D:\Project\venv\Lib\site-packages\django\template\base.py", line 163, in _render
    return self.nodelist.render(context)
           ~~~~~~~~~~~~~~~~~~~~^^^^^^^^^
  File "D:\Project\venv\Lib\site-packages\django\template\base.py", line 1008, in render
    return SafeString("".join([node.render_annotated(context) for node in self]))
                               ~~~~~~~~~~~~~~~~~~~~~^^^^^^^^^
  File "D:\Project\venv\Lib\site-packages\django\template\base.py", line 969, in render_annotated
    return self.render(context)
           ~~~~~~~~~~~^^^^^^^^^
  File "D:\Project\venv\Lib\site-packages\django\template\loader_tags.py", line 65, in render
    result = block.nodelist.render(context)
  File "D:\Project\venv\Lib\site-packages\django\template\base.py", line 1008, in render
    return SafeString("".join([node.render_annotated(context) for node in self]))
                               ~~~~~~~~~~~~~~~~~~~~~^^^^^^^^^
  File "D:\Project\venv\Lib\site-packages\django\template\base.py", line 969, in render_annotated
    return self.render(context)
           ~~~~~~~~~~~^^^^^^^^^
  File "D:\Project\venv\Lib\site-packages\django\template\loader_tags.py", line 65, in render
    result = block.nodelist.render(context)
  File "D:\Project\venv\Lib\site-packages\django\template\base.py", line 1008, in render
    return SafeString("".join([node.render_annotated(context) for node in self]))
                               ~~~~~~~~~~~~~~~~~~~~~^^^^^^^^^
  File "D:\Project\venv\Lib\site-packages\django\template\base.py", line 969, in render_annotated
    return self.render(context)
           ~~~~~~~~~~~^^^^^^^^^
  File "D:\Project\venv\Lib\site-packages\django\contrib\admin\templatetags\base.py", line 45, in render
    return super().render(context)
           ~~~~~~~~~~~~~~^^^^^^^^^
  File "D:\Project\venv\Lib\site-packages\django\template\library.py", line 258, in render
    _dict = self.func(*resolved_args, **resolved_kwargs)
  File "D:\Project\venv\Lib\site-packages\django\contrib\admin\templatetags\admin_list.py", line 346, in result_list
    "results": list(results(cl)),
               ~~~~^^^^^^^^^^^^^
  File "D:\Project\venv\Lib\site-packages\django\contrib\admin\templatetags\admin_list.py", line 319, in results
    yield ResultList(form, items_for_result(cl, res, form))
          ~~~~~~~~~~^^^^^^^^^^^^^^^^^^^^^^^^^^^^^^^^^^^^^^^
  File "D:\Project\venv\Lib\site-packages\django\contrib\admin\templatetags\admin_list.py", line 313, in __init__
    super().__init__(*items)
    ~~~~~~~~~~~~~~~~^^^^^^^^
  File "D:\Project\venv\Lib\site-packages\django\contrib\admin\templatetags\admin_list.py", line 218, in items_for_result
    f, attr, value = lookup_field(field_name, result, cl.model_admin)
                     ~~~~~~~~~~~~^^^^^^^^^^^^^^^^^^^^^^^^^^^^^^^^^^^^
  File "D:\Project\venv\Lib\site-packages\django\contrib\admin\utils.py", line 299, in lookup_field
    value = attr(obj)
  File "D:\Project\base\admin.py", line 97, in teachers_display
    return ", ".join([teacher.username for teacher in obj.teachers.all()])  # Displaying teacher usernames
                                                      ^^^^^^^^^^^^
AttributeError: 'Group' object has no attribute 'teachers'. Did you mean: 'teacher'?
"GET /admin_settings_page/base/group/ HTTP/1.1" 500 477225
Internal Server Error: /admin_settings_page/base/group/
Traceback (most recent call last):
  File "D:\Project\venv\Lib\site-packages\django\db\models\options.py", line 676, in get_field
    return self.fields_map[field_name]
           ~~~~~~~~~~~~~~~^^^^^^^^^^^^
KeyError: 'teachers_display'

During handling of the above exception, another exception occurred:

Traceback (most recent call last):
  File "D:\Project\venv\Lib\site-packages\django\contrib\admin\utils.py", line 290, in lookup_field
    f = _get_non_gfk_field(opts, name)
  File "D:\Project\venv\Lib\site-packages\django\contrib\admin\utils.py", line 330, in _get_non_gfk_field
    field = opts.get_field(name)
  File "D:\Project\venv\Lib\site-packages\django\db\models\options.py", line 678, in get_field
    raise FieldDoesNotExist(
        "%s has no field named '%s'" % (self.object_name, field_name)
    )
django.core.exceptions.FieldDoesNotExist: Group has no field named 'teachers_display'

During handling of the above exception, another exception occurred:

Traceback (most recent call last):
  File "D:\Project\venv\Lib\site-packages\django\core\handlers\exception.py", line 55, in inner
    response = get_response(request)
  File "D:\Project\venv\Lib\site-packages\django\core\handlers\base.py", line 220, in _get_response
    response = response.render()
  File "D:\Project\venv\Lib\site-packages\django\template\response.py", line 114, in render
    self.content = self.rendered_content
                   ^^^^^^^^^^^^^^^^^^^^^
  File "D:\Project\venv\Lib\site-packages\django\template\response.py", line 92, in rendered_content
    return template.render(context, self._request)
           ~~~~~~~~~~~~~~~^^^^^^^^^^^^^^^^^^^^^^^^
  File "D:\Project\venv\Lib\site-packages\django\template\backends\django.py", line 107, in render
    return self.template.render(context)
           ~~~~~~~~~~~~~~~~~~~~^^^^^^^^^
  File "D:\Project\venv\Lib\site-packages\django\template\base.py", line 171, in render
    return self._render(context)
           ~~~~~~~~~~~~^^^^^^^^^
  File "D:\Project\venv\Lib\site-packages\django\template\base.py", line 163, in _render
    return self.nodelist.render(context)
           ~~~~~~~~~~~~~~~~~~~~^^^^^^^^^
  File "D:\Project\venv\Lib\site-packages\django\template\base.py", line 1008, in render
    return SafeString("".join([node.render_annotated(context) for node in self]))
                               ~~~~~~~~~~~~~~~~~~~~~^^^^^^^^^
  File "D:\Project\venv\Lib\site-packages\django\template\base.py", line 969, in render_annotated
    return self.render(context)
           ~~~~~~~~~~~^^^^^^^^^
  File "D:\Project\venv\Lib\site-packages\django\template\loader_tags.py", line 159, in render
    return compiled_parent._render(context)
           ~~~~~~~~~~~~~~~~~~~~~~~^^^^^^^^^
  File "D:\Project\venv\Lib\site-packages\django\template\base.py", line 163, in _render
    return self.nodelist.render(context)
           ~~~~~~~~~~~~~~~~~~~~^^^^^^^^^
  File "D:\Project\venv\Lib\site-packages\django\template\base.py", line 1008, in render
    return SafeString("".join([node.render_annotated(context) for node in self]))
                               ~~~~~~~~~~~~~~~~~~~~~^^^^^^^^^
  File "D:\Project\venv\Lib\site-packages\django\template\base.py", line 969, in render_annotated
    return self.render(context)
           ~~~~~~~~~~~^^^^^^^^^
  File "D:\Project\venv\Lib\site-packages\django\template\loader_tags.py", line 159, in render
    return compiled_parent._render(context)
           ~~~~~~~~~~~~~~~~~~~~~~~^^^^^^^^^
  File "D:\Project\venv\Lib\site-packages\django\template\base.py", line 163, in _render
    return self.nodelist.render(context)
           ~~~~~~~~~~~~~~~~~~~~^^^^^^^^^
  File "D:\Project\venv\Lib\site-packages\django\template\base.py", line 1008, in render
    return SafeString("".join([node.render_annotated(context) for node in self]))
                               ~~~~~~~~~~~~~~~~~~~~~^^^^^^^^^
  File "D:\Project\venv\Lib\site-packages\django\template\base.py", line 969, in render_annotated
    return self.render(context)
           ~~~~~~~~~~~^^^^^^^^^
  File "D:\Project\venv\Lib\site-packages\django\template\loader_tags.py", line 159, in render
    return compiled_parent._render(context)
           ~~~~~~~~~~~~~~~~~~~~~~~^^^^^^^^^
  File "D:\Project\venv\Lib\site-packages\django\template\base.py", line 163, in _render
    return self.nodelist.render(context)
           ~~~~~~~~~~~~~~~~~~~~^^^^^^^^^
  File "D:\Project\venv\Lib\site-packages\django\template\base.py", line 1008, in render
    return SafeString("".join([node.render_annotated(context) for node in self]))
                               ~~~~~~~~~~~~~~~~~~~~~^^^^^^^^^
  File "D:\Project\venv\Lib\site-packages\django\template\base.py", line 969, in render_annotated
    return self.render(context)
           ~~~~~~~~~~~^^^^^^^^^
  File "D:\Project\venv\Lib\site-packages\django\template\loader_tags.py", line 159, in render
    return compiled_parent._render(context)
           ~~~~~~~~~~~~~~~~~~~~~~~^^^^^^^^^
  File "D:\Project\venv\Lib\site-packages\django\template\base.py", line 163, in _render
    return self.nodelist.render(context)
           ~~~~~~~~~~~~~~~~~~~~^^^^^^^^^
  File "D:\Project\venv\Lib\site-packages\django\template\base.py", line 1008, in render
    return SafeString("".join([node.render_annotated(context) for node in self]))
                               ~~~~~~~~~~~~~~~~~~~~~^^^^^^^^^
  File "D:\Project\venv\Lib\site-packages\django\template\base.py", line 969, in render_annotated
    return self.render(context)
           ~~~~~~~~~~~^^^^^^^^^
  File "D:\Project\venv\Lib\site-packages\django\template\loader_tags.py", line 65, in render
    result = block.nodelist.render(context)
  File "D:\Project\venv\Lib\site-packages\django\template\base.py", line 1008, in render
    return SafeString("".join([node.render_annotated(context) for node in self]))
                               ~~~~~~~~~~~~~~~~~~~~~^^^^^^^^^
  File "D:\Project\venv\Lib\site-packages\django\template\base.py", line 969, in render_annotated
    return self.render(context)
           ~~~~~~~~~~~^^^^^^^^^
  File "D:\Project\venv\Lib\site-packages\django\template\loader_tags.py", line 65, in render
    result = block.nodelist.render(context)
  File "D:\Project\venv\Lib\site-packages\django\template\base.py", line 1008, in render
    return SafeString("".join([node.render_annotated(context) for node in self]))
                               ~~~~~~~~~~~~~~~~~~~~~^^^^^^^^^
  File "D:\Project\venv\Lib\site-packages\django\template\base.py", line 969, in render_annotated
    return self.render(context)
           ~~~~~~~~~~~^^^^^^^^^
  File "D:\Project\venv\Lib\site-packages\django\contrib\admin\templatetags\base.py", line 45, in render
    return super().render(context)
           ~~~~~~~~~~~~~~^^^^^^^^^
  File "D:\Project\venv\Lib\site-packages\django\template\library.py", line 258, in render
    _dict = self.func(*resolved_args, **resolved_kwargs)
  File "D:\Project\venv\Lib\site-packages\django\contrib\admin\templatetags\admin_list.py", line 346, in result_list
    "results": list(results(cl)),
               ~~~~^^^^^^^^^^^^^
  File "D:\Project\venv\Lib\site-packages\django\contrib\admin\templatetags\admin_list.py", line 319, in results
    yield ResultList(form, items_for_result(cl, res, form))
          ~~~~~~~~~~^^^^^^^^^^^^^^^^^^^^^^^^^^^^^^^^^^^^^^^
  File "D:\Project\venv\Lib\site-packages\django\contrib\admin\templatetags\admin_list.py", line 313, in __init__
    super().__init__(*items)
    ~~~~~~~~~~~~~~~~^^^^^^^^
  File "D:\Project\venv\Lib\site-packages\django\contrib\admin\templatetags\admin_list.py", line 218, in items_for_result
    f, attr, value = lookup_field(field_name, result, cl.model_admin)
                     ~~~~~~~~~~~~^^^^^^^^^^^^^^^^^^^^^^^^^^^^^^^^^^^^
  File "D:\Project\venv\Lib\site-packages\django\contrib\admin\utils.py", line 299, in lookup_field
    value = attr(obj)
  File "D:\Project\base\admin.py", line 97, in teachers_display
    return ", ".join([teacher.username for teacher in obj.teachers.all()])  # Displaying teacher usernames
                                                      ^^^^^^^^^^^^
AttributeError: 'Group' object has no attribute 'teachers'. Did you mean: 'teacher'?
"GET /admin_settings_page/base/group/ HTTP/1.1" 500 477237
Internal Server Error: /admin_settings_page/base/group/
Traceback (most recent call last):
  File "D:\Project\venv\Lib\site-packages\django\db\models\query.py", line 948, in get_or_create
    return self.get(**kwargs), False
           ~~~~~~~~^^^^^^^^^^
  File "D:\Project\venv\Lib\site-packages\django\db\models\query.py", line 649, in get
    raise self.model.DoesNotExist(
        "%s matching query does not exist." % self.model._meta.object_name
    )
base.models.Attendance.DoesNotExist: Attendance matching query does not exist.

During handling of the above exception, another exception occurred:

Traceback (most recent call last):
  File "D:\Project\venv\Lib\site-packages\django\db\backends\utils.py", line 105, in _execute
    return self.cursor.execute(sql, params)
           ~~~~~~~~~~~~~~~~~~~^^^^^^^^^^^^^
  File "D:\Project\venv\Lib\site-packages\django\db\backends\mysql\base.py", line 76, in execute
    return self.cursor.execute(query, args)
           ~~~~~~~~~~~~~~~~~~~^^^^^^^^^^^^^
  File "D:\Project\venv\Lib\site-packages\MySQLdb\cursors.py", line 179, in execute
    res = self._query(mogrified_query)
  File "D:\Project\venv\Lib\site-packages\MySQLdb\cursors.py", line 330, in _query
    db.query(q)
    ~~~~~~~~^^^
  File "D:\Project\venv\Lib\site-packages\MySQLdb\connections.py", line 280, in query
    _mysql.connection.query(self, query)
    ~~~~~~~~~~~~~~~~~~~~~~~^^^^^^^^^^^^^
MySQLdb.IntegrityError: (1048, "Column 'status' cannot be null")

The above exception was the direct cause of the following exception:

Traceback (most recent call last):
  File "D:\Project\venv\Lib\site-packages\django\core\handlers\exception.py", line 55, in inner
    response = get_response(request)
  File "D:\Project\venv\Lib\site-packages\django\core\handlers\base.py", line 197, in _get_response
    response = wrapped_callback(request, *callback_args, **callback_kwargs)
  File "D:\Project\venv\Lib\site-packages\django\contrib\admin\options.py", line 718, in wrapper
    return self.admin_site.admin_view(view)(*args, **kwargs)
           ~~~~~~~~~~~~~~~~~~~~~~~~~~~~~~~~^^^^^^^^^^^^^^^^^
  File "D:\Project\venv\Lib\site-packages\django\utils\decorators.py", line 188, in _view_wrapper
    result = _process_exception(request, e)
  File "D:\Project\venv\Lib\site-packages\django\utils\decorators.py", line 186, in _view_wrapper
    response = view_func(request, *args, **kwargs)
  File "D:\Project\venv\Lib\site-packages\django\views\decorators\cache.py", line 80, in _view_wrapper
    response = view_func(request, *args, **kwargs)
  File "D:\Project\venv\Lib\site-packages\django\contrib\admin\sites.py", line 241, in inner
    return view(request, *args, **kwargs)
  File "D:\Project\venv\Lib\site-packages\import_export\admin.py", line 811, in changelist_view
    return super().changelist_view(request, extra_context)
           ~~~~~~~~~~~~~~~~~~~~~~~^^^^^^^^^^^^^^^^^^^^^^^^
  File "D:\Project\venv\Lib\site-packages\import_export\admin.py", line 66, in changelist_view
    return super().changelist_view(request, extra_context)
           ~~~~~~~~~~~~~~~~~~~~~~~^^^^^^^^^^^^^^^^^^^^^^^^
  File "D:\Project\venv\Lib\site-packages\django\utils\decorators.py", line 48, in _wrapper
    return bound_method(*args, **kwargs)
  File "D:\Project\venv\Lib\site-packages\django\utils\decorators.py", line 188, in _view_wrapper
    result = _process_exception(request, e)
  File "D:\Project\venv\Lib\site-packages\django\utils\decorators.py", line 186, in _view_wrapper
    response = view_func(request, *args, **kwargs)
  File "D:\Project\venv\Lib\site-packages\django\contrib\admin\options.py", line 2032, in changelist_view
    response = self.response_action(
        request, queryset=cl.get_queryset(request)
    )
  File "D:\Project\venv\Lib\site-packages\django\contrib\admin\options.py", line 1664, in response_action
    response = func(self, request, queryset)
  File "D:\Project\base\admin.py", line 98, in generate_attendance
    generate_attendance_for_group(group.id)
    ~~~~~~~~~~~~~~~~~~~~~~~~~~~~~^^^^^^^^^^
  File "D:\Project\base\utils.py", line 29, in generate_attendance_for_group
    Attendance.objects.get_or_create(student=student, date=sana)
    ~~~~~~~~~~~~~~~~~~~~~~~~~~~~~~~~^^^^^^^^^^^^^^^^^^^^^^^^^^^^
  File "D:\Project\venv\Lib\site-packages\django\db\models\manager.py", line 87, in manager_method
    return getattr(self.get_queryset(), name)(*args, **kwargs)
           ~~~~~~~~~~~~~~~~~~~~~~~~~~~~~~~~~~^^^^^^^^^^^^^^^^^
  File "D:\Project\venv\Lib\site-packages\django\db\models\query.py", line 955, in get_or_create
    return self.create(**params), True
           ~~~~~~~~~~~^^^^^^^^^^
  File "D:\Project\venv\Lib\site-packages\django\db\models\query.py", line 679, in create
    obj.save(force_insert=True, using=self.db)
    ~~~~~~~~^^^^^^^^^^^^^^^^^^^^^^^^^^^^^^^^^^
  File "D:\Project\venv\Lib\site-packages\django\db\models\base.py", line 892, in save
    self.save_base(
    ~~~~~~~~~~~~~~^
        using=using,
        ^^^^^^^^^^^^
    ...<2 lines>...
        update_fields=update_fields,
        ^^^^^^^^^^^^^^^^^^^^^^^^^^^^
    )
    ^
  File "D:\Project\venv\Lib\site-packages\django\db\models\base.py", line 998, in save_base
    updated = self._save_table(
        raw,
    ...<4 lines>...
        update_fields,
    )
  File "D:\Project\venv\Lib\site-packages\django\db\models\base.py", line 1161, in _save_table
    results = self._do_insert(
        cls._base_manager, using, fields, returning_fields, raw
    )
  File "D:\Project\venv\Lib\site-packages\django\db\models\base.py", line 1202, in _do_insert
    return manager._insert(
           ~~~~~~~~~~~~~~~^
        [self],
        ^^^^^^^
    ...<3 lines>...
        raw=raw,
        ^^^^^^^^
    )
    ^
  File "D:\Project\venv\Lib\site-packages\django\db\models\manager.py", line 87, in manager_method
    return getattr(self.get_queryset(), name)(*args, **kwargs)
           ~~~~~~~~~~~~~~~~~~~~~~~~~~~~~~~~~~^^^^^^^^^^^^^^^^^
  File "D:\Project\venv\Lib\site-packages\django\db\models\query.py", line 1847, in _insert
    return query.get_compiler(using=using).execute_sql(returning_fields)
           ~~~~~~~~~~~~~~~~~~~~~~~~~~~~~~~~~~~~~~~~~~~^^^^^^^^^^^^^^^^^^
  File "D:\Project\venv\Lib\site-packages\django\db\models\sql\compiler.py", line 1836, in execute_sql
    cursor.execute(sql, params)
    ~~~~~~~~~~~~~~^^^^^^^^^^^^^
  File "D:\Project\venv\Lib\site-packages\django\db\backends\utils.py", line 122, in execute
    return super().execute(sql, params)
           ~~~~~~~~~~~~~~~^^^^^^^^^^^^^
  File "D:\Project\venv\Lib\site-packages\django\db\backends\utils.py", line 79, in execute
    return self._execute_with_wrappers(
           ~~~~~~~~~~~~~~~~~~~~~~~~~~~^
        sql, params, many=False, executor=self._execute
        ^^^^^^^^^^^^^^^^^^^^^^^^^^^^^^^^^^^^^^^^^^^^^^^
    )
    ^
  File "D:\Project\venv\Lib\site-packages\django\db\backends\utils.py", line 92, in _execute_with_wrappers
    return executor(sql, params, many, context)
  File "D:\Project\venv\Lib\site-packages\django\db\backends\utils.py", line 100, in _execute
    with self.db.wrap_database_errors:
         ^^^^^^^^^^^^^^^^^^^^^^^^^^^^
  File "D:\Project\venv\Lib\site-packages\django\db\utils.py", line 91, in __exit__
    raise dj_exc_value.with_traceback(traceback) from exc_value
  File "D:\Project\venv\Lib\site-packages\django\db\backends\utils.py", line 105, in _execute
    return self.cursor.execute(sql, params)
           ~~~~~~~~~~~~~~~~~~~^^^^^^^^^^^^^
  File "D:\Project\venv\Lib\site-packages\django\db\backends\mysql\base.py", line 76, in execute
    return self.cursor.execute(query, args)
           ~~~~~~~~~~~~~~~~~~~^^^^^^^^^^^^^
  File "D:\Project\venv\Lib\site-packages\MySQLdb\cursors.py", line 179, in execute
    res = self._query(mogrified_query)
  File "D:\Project\venv\Lib\site-packages\MySQLdb\cursors.py", line 330, in _query
    db.query(q)
    ~~~~~~~~^^^
  File "D:\Project\venv\Lib\site-packages\MySQLdb\connections.py", line 280, in query
    _mysql.connection.query(self, query)
    ~~~~~~~~~~~~~~~~~~~~~~~^^^^^^^^^^^^^
django.db.utils.IntegrityError: (1048, "Column 'status' cannot be null")
"POST /admin_settings_page/base/group/ HTTP/1.1" 500 266629
Internal Server Error: /admin_settings_page/base/group/
Traceback (most recent call last):
  File "D:\Project\venv\Lib\site-packages\django\db\models\query.py", line 948, in get_or_create
    return self.get(**kwargs), False
           ~~~~~~~~^^^^^^^^^^
  File "D:\Project\venv\Lib\site-packages\django\db\models\query.py", line 649, in get
    raise self.model.DoesNotExist(
        "%s matching query does not exist." % self.model._meta.object_name
    )
base.models.Attendance.DoesNotExist: Attendance matching query does not exist.

During handling of the above exception, another exception occurred:

Traceback (most recent call last):
  File "D:\Project\venv\Lib\site-packages\django\db\backends\utils.py", line 105, in _execute
    return self.cursor.execute(sql, params)
           ~~~~~~~~~~~~~~~~~~~^^^^^^^^^^^^^
  File "D:\Project\venv\Lib\site-packages\django\db\backends\mysql\base.py", line 76, in execute
    return self.cursor.execute(query, args)
           ~~~~~~~~~~~~~~~~~~~^^^^^^^^^^^^^
  File "D:\Project\venv\Lib\site-packages\MySQLdb\cursors.py", line 179, in execute
    res = self._query(mogrified_query)
  File "D:\Project\venv\Lib\site-packages\MySQLdb\cursors.py", line 330, in _query
    db.query(q)
    ~~~~~~~~^^^
  File "D:\Project\venv\Lib\site-packages\MySQLdb\connections.py", line 280, in query
    _mysql.connection.query(self, query)
    ~~~~~~~~~~~~~~~~~~~~~~~^^^^^^^^^^^^^
MySQLdb.IntegrityError: (1048, "Column 'status' cannot be null")

The above exception was the direct cause of the following exception:

Traceback (most recent call last):
  File "D:\Project\venv\Lib\site-packages\django\core\handlers\exception.py", line 55, in inner
    response = get_response(request)
  File "D:\Project\venv\Lib\site-packages\django\core\handlers\base.py", line 197, in _get_response
    response = wrapped_callback(request, *callback_args, **callback_kwargs)
  File "D:\Project\venv\Lib\site-packages\django\contrib\admin\options.py", line 718, in wrapper
    return self.admin_site.admin_view(view)(*args, **kwargs)
           ~~~~~~~~~~~~~~~~~~~~~~~~~~~~~~~~^^^^^^^^^^^^^^^^^
  File "D:\Project\venv\Lib\site-packages\django\utils\decorators.py", line 188, in _view_wrapper
    result = _process_exception(request, e)
  File "D:\Project\venv\Lib\site-packages\django\utils\decorators.py", line 186, in _view_wrapper
    response = view_func(request, *args, **kwargs)
  File "D:\Project\venv\Lib\site-packages\django\views\decorators\cache.py", line 80, in _view_wrapper
    response = view_func(request, *args, **kwargs)
  File "D:\Project\venv\Lib\site-packages\django\contrib\admin\sites.py", line 241, in inner
    return view(request, *args, **kwargs)
  File "D:\Project\venv\Lib\site-packages\import_export\admin.py", line 811, in changelist_view
    return super().changelist_view(request, extra_context)
           ~~~~~~~~~~~~~~~~~~~~~~~^^^^^^^^^^^^^^^^^^^^^^^^
  File "D:\Project\venv\Lib\site-packages\import_export\admin.py", line 66, in changelist_view
    return super().changelist_view(request, extra_context)
           ~~~~~~~~~~~~~~~~~~~~~~~^^^^^^^^^^^^^^^^^^^^^^^^
  File "D:\Project\venv\Lib\site-packages\django\utils\decorators.py", line 48, in _wrapper
    return bound_method(*args, **kwargs)
  File "D:\Project\venv\Lib\site-packages\django\utils\decorators.py", line 188, in _view_wrapper
    result = _process_exception(request, e)
  File "D:\Project\venv\Lib\site-packages\django\utils\decorators.py", line 186, in _view_wrapper
    response = view_func(request, *args, **kwargs)
  File "D:\Project\venv\Lib\site-packages\django\contrib\admin\options.py", line 2032, in changelist_view
    response = self.response_action(
        request, queryset=cl.get_queryset(request)
    )
  File "D:\Project\venv\Lib\site-packages\django\contrib\admin\options.py", line 1664, in response_action
    response = func(self, request, queryset)
  File "D:\Project\base\admin.py", line 98, in generate_attendance
    generate_attendance_for_group(group.id)
    ~~~~~~~~~~~~~~~~~~~~~~~~~~~~~^^^^^^^^^^
  File "D:\Project\base\utils.py", line 29, in generate_attendance_for_group
    Attendance.objects.get_or_create(student=student, date=sana)
    ~~~~~~~~~~~~~~~~~~~~~~~~~~~~~~~~^^^^^^^^^^^^^^^^^^^^^^^^^^^^
  File "D:\Project\venv\Lib\site-packages\django\db\models\manager.py", line 87, in manager_method
    return getattr(self.get_queryset(), name)(*args, **kwargs)
           ~~~~~~~~~~~~~~~~~~~~~~~~~~~~~~~~~~^^^^^^^^^^^^^^^^^
  File "D:\Project\venv\Lib\site-packages\django\db\models\query.py", line 955, in get_or_create
    return self.create(**params), True
           ~~~~~~~~~~~^^^^^^^^^^
  File "D:\Project\venv\Lib\site-packages\django\db\models\query.py", line 679, in create
    obj.save(force_insert=True, using=self.db)
    ~~~~~~~~^^^^^^^^^^^^^^^^^^^^^^^^^^^^^^^^^^
  File "D:\Project\venv\Lib\site-packages\django\db\models\base.py", line 892, in save
    self.save_base(
    ~~~~~~~~~~~~~~^
        using=using,
        ^^^^^^^^^^^^
    ...<2 lines>...
        update_fields=update_fields,
        ^^^^^^^^^^^^^^^^^^^^^^^^^^^^
    )
    ^
  File "D:\Project\venv\Lib\site-packages\django\db\models\base.py", line 998, in save_base
    updated = self._save_table(
        raw,
    ...<4 lines>...
        update_fields,
    )
  File "D:\Project\venv\Lib\site-packages\django\db\models\base.py", line 1161, in _save_table
    results = self._do_insert(
        cls._base_manager, using, fields, returning_fields, raw
    )
  File "D:\Project\venv\Lib\site-packages\django\db\models\base.py", line 1202, in _do_insert
    return manager._insert(
           ~~~~~~~~~~~~~~~^
        [self],
        ^^^^^^^
    ...<3 lines>...
        raw=raw,
        ^^^^^^^^
    )
    ^
  File "D:\Project\venv\Lib\site-packages\django\db\models\manager.py", line 87, in manager_method
    return getattr(self.get_queryset(), name)(*args, **kwargs)
           ~~~~~~~~~~~~~~~~~~~~~~~~~~~~~~~~~~^^^^^^^^^^^^^^^^^
  File "D:\Project\venv\Lib\site-packages\django\db\models\query.py", line 1847, in _insert
    return query.get_compiler(using=using).execute_sql(returning_fields)
           ~~~~~~~~~~~~~~~~~~~~~~~~~~~~~~~~~~~~~~~~~~~^^^^^^^^^^^^^^^^^^
  File "D:\Project\venv\Lib\site-packages\django\db\models\sql\compiler.py", line 1836, in execute_sql
    cursor.execute(sql, params)
    ~~~~~~~~~~~~~~^^^^^^^^^^^^^
  File "D:\Project\venv\Lib\site-packages\django\db\backends\utils.py", line 122, in execute
    return super().execute(sql, params)
           ~~~~~~~~~~~~~~~^^^^^^^^^^^^^
  File "D:\Project\venv\Lib\site-packages\django\db\backends\utils.py", line 79, in execute
    return self._execute_with_wrappers(
           ~~~~~~~~~~~~~~~~~~~~~~~~~~~^
        sql, params, many=False, executor=self._execute
        ^^^^^^^^^^^^^^^^^^^^^^^^^^^^^^^^^^^^^^^^^^^^^^^
    )
    ^
  File "D:\Project\venv\Lib\site-packages\django\db\backends\utils.py", line 92, in _execute_with_wrappers
    return executor(sql, params, many, context)
  File "D:\Project\venv\Lib\site-packages\django\db\backends\utils.py", line 100, in _execute
    with self.db.wrap_database_errors:
         ^^^^^^^^^^^^^^^^^^^^^^^^^^^^
  File "D:\Project\venv\Lib\site-packages\django\db\utils.py", line 91, in __exit__
    raise dj_exc_value.with_traceback(traceback) from exc_value
  File "D:\Project\venv\Lib\site-packages\django\db\backends\utils.py", line 105, in _execute
    return self.cursor.execute(sql, params)
           ~~~~~~~~~~~~~~~~~~~^^^^^^^^^^^^^
  File "D:\Project\venv\Lib\site-packages\django\db\backends\mysql\base.py", line 76, in execute
    return self.cursor.execute(query, args)
           ~~~~~~~~~~~~~~~~~~~^^^^^^^^^^^^^
  File "D:\Project\venv\Lib\site-packages\MySQLdb\cursors.py", line 179, in execute
    res = self._query(mogrified_query)
  File "D:\Project\venv\Lib\site-packages\MySQLdb\cursors.py", line 330, in _query
    db.query(q)
    ~~~~~~~~^^^
  File "D:\Project\venv\Lib\site-packages\MySQLdb\connections.py", line 280, in query
    _mysql.connection.query(self, query)
    ~~~~~~~~~~~~~~~~~~~~~~~^^^^^^^^^^^^^
django.db.utils.IntegrityError: (1048, "Column 'status' cannot be null")
"POST /admin_settings_page/base/group/ HTTP/1.1" 500 266713
Internal Server Error: /admin_settings_page/base/group/
Traceback (most recent call last):
  File "D:\Project\venv\Lib\site-packages\django\db\models\query.py", line 948, in get_or_create
    return self.get(**kwargs), False
           ~~~~~~~~^^^^^^^^^^
  File "D:\Project\venv\Lib\site-packages\django\db\models\query.py", line 649, in get
    raise self.model.DoesNotExist(
        "%s matching query does not exist." % self.model._meta.object_name
    )
base.models.Attendance.DoesNotExist: Attendance matching query does not exist.

During handling of the above exception, another exception occurred:

Traceback (most recent call last):
  File "D:\Project\venv\Lib\site-packages\django\db\backends\utils.py", line 105, in _execute
    return self.cursor.execute(sql, params)
           ~~~~~~~~~~~~~~~~~~~^^^^^^^^^^^^^
  File "D:\Project\venv\Lib\site-packages\django\db\backends\mysql\base.py", line 76, in execute
    return self.cursor.execute(query, args)
           ~~~~~~~~~~~~~~~~~~~^^^^^^^^^^^^^
  File "D:\Project\venv\Lib\site-packages\MySQLdb\cursors.py", line 179, in execute
    res = self._query(mogrified_query)
  File "D:\Project\venv\Lib\site-packages\MySQLdb\cursors.py", line 330, in _query
    db.query(q)
    ~~~~~~~~^^^
  File "D:\Project\venv\Lib\site-packages\MySQLdb\connections.py", line 280, in query
    _mysql.connection.query(self, query)
    ~~~~~~~~~~~~~~~~~~~~~~~^^^^^^^^^^^^^
MySQLdb.IntegrityError: (1048, "Column 'status' cannot be null")

The above exception was the direct cause of the following exception:

Traceback (most recent call last):
  File "D:\Project\venv\Lib\site-packages\django\core\handlers\exception.py", line 55, in inner
    response = get_response(request)
  File "D:\Project\venv\Lib\site-packages\django\core\handlers\base.py", line 197, in _get_response
    response = wrapped_callback(request, *callback_args, **callback_kwargs)
  File "D:\Project\venv\Lib\site-packages\django\contrib\admin\options.py", line 718, in wrapper
    return self.admin_site.admin_view(view)(*args, **kwargs)
           ~~~~~~~~~~~~~~~~~~~~~~~~~~~~~~~~^^^^^^^^^^^^^^^^^
  File "D:\Project\venv\Lib\site-packages\django\utils\decorators.py", line 188, in _view_wrapper
    result = _process_exception(request, e)
  File "D:\Project\venv\Lib\site-packages\django\utils\decorators.py", line 186, in _view_wrapper
    response = view_func(request, *args, **kwargs)
  File "D:\Project\venv\Lib\site-packages\django\views\decorators\cache.py", line 80, in _view_wrapper
    response = view_func(request, *args, **kwargs)
  File "D:\Project\venv\Lib\site-packages\django\contrib\admin\sites.py", line 241, in inner
    return view(request, *args, **kwargs)
  File "D:\Project\venv\Lib\site-packages\import_export\admin.py", line 811, in changelist_view
    return super().changelist_view(request, extra_context)
           ~~~~~~~~~~~~~~~~~~~~~~~^^^^^^^^^^^^^^^^^^^^^^^^
  File "D:\Project\venv\Lib\site-packages\import_export\admin.py", line 66, in changelist_view
    return super().changelist_view(request, extra_context)
           ~~~~~~~~~~~~~~~~~~~~~~~^^^^^^^^^^^^^^^^^^^^^^^^
  File "D:\Project\venv\Lib\site-packages\django\utils\decorators.py", line 48, in _wrapper
    return bound_method(*args, **kwargs)
  File "D:\Project\venv\Lib\site-packages\django\utils\decorators.py", line 188, in _view_wrapper
    result = _process_exception(request, e)
  File "D:\Project\venv\Lib\site-packages\django\utils\decorators.py", line 186, in _view_wrapper
    response = view_func(request, *args, **kwargs)
  File "D:\Project\venv\Lib\site-packages\django\contrib\admin\options.py", line 2032, in changelist_view
    response = self.response_action(
        request, queryset=cl.get_queryset(request)
    )
  File "D:\Project\venv\Lib\site-packages\django\contrib\admin\options.py", line 1664, in response_action
    response = func(self, request, queryset)
  File "D:\Project\base\admin.py", line 98, in generate_attendance
    generate_attendance_for_group(group.id)
    ~~~~~~~~~~~~~~~~~~~~~~~~~~~~~^^^^^^^^^^
  File "D:\Project\base\utils.py", line 29, in generate_attendance_for_group
    Attendance.objects.get_or_create(student=student, date=sana)
    ~~~~~~~~~~~~~~~~~~~~~~~~~~~~~~~~^^^^^^^^^^^^^^^^^^^^^^^^^^^^
  File "D:\Project\venv\Lib\site-packages\django\db\models\manager.py", line 87, in manager_method
    return getattr(self.get_queryset(), name)(*args, **kwargs)
           ~~~~~~~~~~~~~~~~~~~~~~~~~~~~~~~~~~^^^^^^^^^^^^^^^^^
  File "D:\Project\venv\Lib\site-packages\django\db\models\query.py", line 955, in get_or_create
    return self.create(**params), True
           ~~~~~~~~~~~^^^^^^^^^^
  File "D:\Project\venv\Lib\site-packages\django\db\models\query.py", line 679, in create
    obj.save(force_insert=True, using=self.db)
    ~~~~~~~~^^^^^^^^^^^^^^^^^^^^^^^^^^^^^^^^^^
  File "D:\Project\venv\Lib\site-packages\django\db\models\base.py", line 892, in save
    self.save_base(
    ~~~~~~~~~~~~~~^
        using=using,
        ^^^^^^^^^^^^
    ...<2 lines>...
        update_fields=update_fields,
        ^^^^^^^^^^^^^^^^^^^^^^^^^^^^
    )
    ^
  File "D:\Project\venv\Lib\site-packages\django\db\models\base.py", line 998, in save_base
    updated = self._save_table(
        raw,
    ...<4 lines>...
        update_fields,
    )
  File "D:\Project\venv\Lib\site-packages\django\db\models\base.py", line 1161, in _save_table
    results = self._do_insert(
        cls._base_manager, using, fields, returning_fields, raw
    )
  File "D:\Project\venv\Lib\site-packages\django\db\models\base.py", line 1202, in _do_insert
    return manager._insert(
           ~~~~~~~~~~~~~~~^
        [self],
        ^^^^^^^
    ...<3 lines>...
        raw=raw,
        ^^^^^^^^
    )
    ^
  File "D:\Project\venv\Lib\site-packages\django\db\models\manager.py", line 87, in manager_method
    return getattr(self.get_queryset(), name)(*args, **kwargs)
           ~~~~~~~~~~~~~~~~~~~~~~~~~~~~~~~~~~^^^^^^^^^^^^^^^^^
  File "D:\Project\venv\Lib\site-packages\django\db\models\query.py", line 1847, in _insert
    return query.get_compiler(using=using).execute_sql(returning_fields)
           ~~~~~~~~~~~~~~~~~~~~~~~~~~~~~~~~~~~~~~~~~~~^^^^^^^^^^^^^^^^^^
  File "D:\Project\venv\Lib\site-packages\django\db\models\sql\compiler.py", line 1836, in execute_sql
    cursor.execute(sql, params)
    ~~~~~~~~~~~~~~^^^^^^^^^^^^^
  File "D:\Project\venv\Lib\site-packages\django\db\backends\utils.py", line 122, in execute
    return super().execute(sql, params)
           ~~~~~~~~~~~~~~~^^^^^^^^^^^^^
  File "D:\Project\venv\Lib\site-packages\django\db\backends\utils.py", line 79, in execute
    return self._execute_with_wrappers(
           ~~~~~~~~~~~~~~~~~~~~~~~~~~~^
        sql, params, many=False, executor=self._execute
        ^^^^^^^^^^^^^^^^^^^^^^^^^^^^^^^^^^^^^^^^^^^^^^^
    )
    ^
  File "D:\Project\venv\Lib\site-packages\django\db\backends\utils.py", line 92, in _execute_with_wrappers
    return executor(sql, params, many, context)
  File "D:\Project\venv\Lib\site-packages\django\db\backends\utils.py", line 100, in _execute
    with self.db.wrap_database_errors:
         ^^^^^^^^^^^^^^^^^^^^^^^^^^^^
  File "D:\Project\venv\Lib\site-packages\django\db\utils.py", line 91, in __exit__
    raise dj_exc_value.with_traceback(traceback) from exc_value
  File "D:\Project\venv\Lib\site-packages\django\db\backends\utils.py", line 105, in _execute
    return self.cursor.execute(sql, params)
           ~~~~~~~~~~~~~~~~~~~^^^^^^^^^^^^^
  File "D:\Project\venv\Lib\site-packages\django\db\backends\mysql\base.py", line 76, in execute
    return self.cursor.execute(query, args)
           ~~~~~~~~~~~~~~~~~~~^^^^^^^^^^^^^
  File "D:\Project\venv\Lib\site-packages\MySQLdb\cursors.py", line 179, in execute
    res = self._query(mogrified_query)
  File "D:\Project\venv\Lib\site-packages\MySQLdb\cursors.py", line 330, in _query
    db.query(q)
    ~~~~~~~~^^^
  File "D:\Project\venv\Lib\site-packages\MySQLdb\connections.py", line 280, in query
    _mysql.connection.query(self, query)
    ~~~~~~~~~~~~~~~~~~~~~~~^^^^^^^^^^^^^
django.db.utils.IntegrityError: (1048, "Column 'status' cannot be null")
"POST /admin_settings_page/base/group/ HTTP/1.1" 500 266713
Internal Server Error: /admin_settings_page/base/group/
Traceback (most recent call last):
  File "D:\Project\venv\Lib\site-packages\django\db\models\query.py", line 948, in get_or_create
    return self.get(**kwargs), False
           ~~~~~~~~^^^^^^^^^^
  File "D:\Project\venv\Lib\site-packages\django\db\models\query.py", line 649, in get
    raise self.model.DoesNotExist(
        "%s matching query does not exist." % self.model._meta.object_name
    )
base.models.Attendance.DoesNotExist: Attendance matching query does not exist.

During handling of the above exception, another exception occurred:

Traceback (most recent call last):
  File "D:\Project\venv\Lib\site-packages\django\db\backends\utils.py", line 105, in _execute
    return self.cursor.execute(sql, params)
           ~~~~~~~~~~~~~~~~~~~^^^^^^^^^^^^^
  File "D:\Project\venv\Lib\site-packages\django\db\backends\mysql\base.py", line 76, in execute
    return self.cursor.execute(query, args)
           ~~~~~~~~~~~~~~~~~~~^^^^^^^^^^^^^
  File "D:\Project\venv\Lib\site-packages\MySQLdb\cursors.py", line 179, in execute
    res = self._query(mogrified_query)
  File "D:\Project\venv\Lib\site-packages\MySQLdb\cursors.py", line 330, in _query
    db.query(q)
    ~~~~~~~~^^^
  File "D:\Project\venv\Lib\site-packages\MySQLdb\connections.py", line 280, in query
    _mysql.connection.query(self, query)
    ~~~~~~~~~~~~~~~~~~~~~~~^^^^^^^^^^^^^
MySQLdb.IntegrityError: (1048, "Column 'status' cannot be null")

The above exception was the direct cause of the following exception:

Traceback (most recent call last):
  File "D:\Project\venv\Lib\site-packages\django\core\handlers\exception.py", line 55, in inner
    response = get_response(request)
  File "D:\Project\venv\Lib\site-packages\django\core\handlers\base.py", line 197, in _get_response
    response = wrapped_callback(request, *callback_args, **callback_kwargs)
  File "D:\Project\venv\Lib\site-packages\django\contrib\admin\options.py", line 718, in wrapper
    return self.admin_site.admin_view(view)(*args, **kwargs)
           ~~~~~~~~~~~~~~~~~~~~~~~~~~~~~~~~^^^^^^^^^^^^^^^^^
  File "D:\Project\venv\Lib\site-packages\django\utils\decorators.py", line 188, in _view_wrapper
    result = _process_exception(request, e)
  File "D:\Project\venv\Lib\site-packages\django\utils\decorators.py", line 186, in _view_wrapper
    response = view_func(request, *args, **kwargs)
  File "D:\Project\venv\Lib\site-packages\django\views\decorators\cache.py", line 80, in _view_wrapper
    response = view_func(request, *args, **kwargs)
  File "D:\Project\venv\Lib\site-packages\django\contrib\admin\sites.py", line 241, in inner
    return view(request, *args, **kwargs)
  File "D:\Project\venv\Lib\site-packages\import_export\admin.py", line 811, in changelist_view
    return super().changelist_view(request, extra_context)
           ~~~~~~~~~~~~~~~~~~~~~~~^^^^^^^^^^^^^^^^^^^^^^^^
  File "D:\Project\venv\Lib\site-packages\import_export\admin.py", line 66, in changelist_view
    return super().changelist_view(request, extra_context)
           ~~~~~~~~~~~~~~~~~~~~~~~^^^^^^^^^^^^^^^^^^^^^^^^
  File "D:\Project\venv\Lib\site-packages\django\utils\decorators.py", line 48, in _wrapper
    return bound_method(*args, **kwargs)
  File "D:\Project\venv\Lib\site-packages\django\utils\decorators.py", line 188, in _view_wrapper
    result = _process_exception(request, e)
  File "D:\Project\venv\Lib\site-packages\django\utils\decorators.py", line 186, in _view_wrapper
    response = view_func(request, *args, **kwargs)
  File "D:\Project\venv\Lib\site-packages\django\contrib\admin\options.py", line 2032, in changelist_view
    response = self.response_action(
        request, queryset=cl.get_queryset(request)
    )
  File "D:\Project\venv\Lib\site-packages\django\contrib\admin\options.py", line 1664, in response_action
    response = func(self, request, queryset)
  File "D:\Project\base\admin.py", line 98, in generate_attendance
    generate_attendance_for_group(group.id)
    ~~~~~~~~~~~~~~~~~~~~~~~~~~~~~^^^^^^^^^^
  File "D:\Project\base\utils.py", line 29, in generate_attendance_for_group
    Attendance.objects.get_or_create(student=student, date=sana)
    ~~~~~~~~~~~~~~~~~~~~~~~~~~~~~~~~^^^^^^^^^^^^^^^^^^^^^^^^^^^^
  File "D:\Project\venv\Lib\site-packages\django\db\models\manager.py", line 87, in manager_method
    return getattr(self.get_queryset(), name)(*args, **kwargs)
           ~~~~~~~~~~~~~~~~~~~~~~~~~~~~~~~~~~^^^^^^^^^^^^^^^^^
  File "D:\Project\venv\Lib\site-packages\django\db\models\query.py", line 955, in get_or_create
    return self.create(**params), True
           ~~~~~~~~~~~^^^^^^^^^^
  File "D:\Project\venv\Lib\site-packages\django\db\models\query.py", line 679, in create
    obj.save(force_insert=True, using=self.db)
    ~~~~~~~~^^^^^^^^^^^^^^^^^^^^^^^^^^^^^^^^^^
  File "D:\Project\venv\Lib\site-packages\django\db\models\base.py", line 892, in save
    self.save_base(
    ~~~~~~~~~~~~~~^
        using=using,
        ^^^^^^^^^^^^
    ...<2 lines>...
        update_fields=update_fields,
        ^^^^^^^^^^^^^^^^^^^^^^^^^^^^
    )
    ^
  File "D:\Project\venv\Lib\site-packages\django\db\models\base.py", line 998, in save_base
    updated = self._save_table(
        raw,
    ...<4 lines>...
        update_fields,
    )
  File "D:\Project\venv\Lib\site-packages\django\db\models\base.py", line 1161, in _save_table
    results = self._do_insert(
        cls._base_manager, using, fields, returning_fields, raw
    )
  File "D:\Project\venv\Lib\site-packages\django\db\models\base.py", line 1202, in _do_insert
    return manager._insert(
           ~~~~~~~~~~~~~~~^
        [self],
        ^^^^^^^
    ...<3 lines>...
        raw=raw,
        ^^^^^^^^
    )
    ^
  File "D:\Project\venv\Lib\site-packages\django\db\models\manager.py", line 87, in manager_method
    return getattr(self.get_queryset(), name)(*args, **kwargs)
           ~~~~~~~~~~~~~~~~~~~~~~~~~~~~~~~~~~^^^^^^^^^^^^^^^^^
  File "D:\Project\venv\Lib\site-packages\django\db\models\query.py", line 1847, in _insert
    return query.get_compiler(using=using).execute_sql(returning_fields)
           ~~~~~~~~~~~~~~~~~~~~~~~~~~~~~~~~~~~~~~~~~~~^^^^^^^^^^^^^^^^^^
  File "D:\Project\venv\Lib\site-packages\django\db\models\sql\compiler.py", line 1836, in execute_sql
    cursor.execute(sql, params)
    ~~~~~~~~~~~~~~^^^^^^^^^^^^^
  File "D:\Project\venv\Lib\site-packages\django\db\backends\utils.py", line 122, in execute
    return super().execute(sql, params)
           ~~~~~~~~~~~~~~~^^^^^^^^^^^^^
  File "D:\Project\venv\Lib\site-packages\django\db\backends\utils.py", line 79, in execute
    return self._execute_with_wrappers(
           ~~~~~~~~~~~~~~~~~~~~~~~~~~~^
        sql, params, many=False, executor=self._execute
        ^^^^^^^^^^^^^^^^^^^^^^^^^^^^^^^^^^^^^^^^^^^^^^^
    )
    ^
  File "D:\Project\venv\Lib\site-packages\django\db\backends\utils.py", line 92, in _execute_with_wrappers
    return executor(sql, params, many, context)
  File "D:\Project\venv\Lib\site-packages\django\db\backends\utils.py", line 100, in _execute
    with self.db.wrap_database_errors:
         ^^^^^^^^^^^^^^^^^^^^^^^^^^^^
  File "D:\Project\venv\Lib\site-packages\django\db\utils.py", line 91, in __exit__
    raise dj_exc_value.with_traceback(traceback) from exc_value
  File "D:\Project\venv\Lib\site-packages\django\db\backends\utils.py", line 105, in _execute
    return self.cursor.execute(sql, params)
           ~~~~~~~~~~~~~~~~~~~^^^^^^^^^^^^^
  File "D:\Project\venv\Lib\site-packages\django\db\backends\mysql\base.py", line 76, in execute
    return self.cursor.execute(query, args)
           ~~~~~~~~~~~~~~~~~~~^^^^^^^^^^^^^
  File "D:\Project\venv\Lib\site-packages\MySQLdb\cursors.py", line 179, in execute
    res = self._query(mogrified_query)
  File "D:\Project\venv\Lib\site-packages\MySQLdb\cursors.py", line 330, in _query
    db.query(q)
    ~~~~~~~~^^^
  File "D:\Project\venv\Lib\site-packages\MySQLdb\connections.py", line 280, in query
    _mysql.connection.query(self, query)
    ~~~~~~~~~~~~~~~~~~~~~~~^^^^^^^^^^^^^
django.db.utils.IntegrityError: (1048, "Column 'status' cannot be null")
"POST /admin_settings_page/base/group/ HTTP/1.1" 500 266629
Internal Server Error: /admin_settings_page/base/group/
Traceback (most recent call last):
  File "D:\Project\venv\Lib\site-packages\django\db\models\query.py", line 948, in get_or_create
    return self.get(**kwargs), False
           ~~~~~~~~^^^^^^^^^^
  File "D:\Project\venv\Lib\site-packages\django\db\models\query.py", line 649, in get
    raise self.model.DoesNotExist(
        "%s matching query does not exist." % self.model._meta.object_name
    )
base.models.Attendance.DoesNotExist: Attendance matching query does not exist.

During handling of the above exception, another exception occurred:

Traceback (most recent call last):
  File "D:\Project\venv\Lib\site-packages\django\db\backends\utils.py", line 105, in _execute
    return self.cursor.execute(sql, params)
           ~~~~~~~~~~~~~~~~~~~^^^^^^^^^^^^^
  File "D:\Project\venv\Lib\site-packages\django\db\backends\mysql\base.py", line 76, in execute
    return self.cursor.execute(query, args)
           ~~~~~~~~~~~~~~~~~~~^^^^^^^^^^^^^
  File "D:\Project\venv\Lib\site-packages\MySQLdb\cursors.py", line 179, in execute
    res = self._query(mogrified_query)
  File "D:\Project\venv\Lib\site-packages\MySQLdb\cursors.py", line 330, in _query
    db.query(q)
    ~~~~~~~~^^^
  File "D:\Project\venv\Lib\site-packages\MySQLdb\connections.py", line 280, in query
    _mysql.connection.query(self, query)
    ~~~~~~~~~~~~~~~~~~~~~~~^^^^^^^^^^^^^
MySQLdb.IntegrityError: (1048, "Column 'status' cannot be null")

The above exception was the direct cause of the following exception:

Traceback (most recent call last):
  File "D:\Project\venv\Lib\site-packages\django\core\handlers\exception.py", line 55, in inner
    response = get_response(request)
  File "D:\Project\venv\Lib\site-packages\django\core\handlers\base.py", line 197, in _get_response
    response = wrapped_callback(request, *callback_args, **callback_kwargs)
  File "D:\Project\venv\Lib\site-packages\django\contrib\admin\options.py", line 718, in wrapper
    return self.admin_site.admin_view(view)(*args, **kwargs)
           ~~~~~~~~~~~~~~~~~~~~~~~~~~~~~~~~^^^^^^^^^^^^^^^^^
  File "D:\Project\venv\Lib\site-packages\django\utils\decorators.py", line 188, in _view_wrapper
    result = _process_exception(request, e)
  File "D:\Project\venv\Lib\site-packages\django\utils\decorators.py", line 186, in _view_wrapper
    response = view_func(request, *args, **kwargs)
  File "D:\Project\venv\Lib\site-packages\django\views\decorators\cache.py", line 80, in _view_wrapper
    response = view_func(request, *args, **kwargs)
  File "D:\Project\venv\Lib\site-packages\django\contrib\admin\sites.py", line 241, in inner
    return view(request, *args, **kwargs)
  File "D:\Project\venv\Lib\site-packages\import_export\admin.py", line 811, in changelist_view
    return super().changelist_view(request, extra_context)
           ~~~~~~~~~~~~~~~~~~~~~~~^^^^^^^^^^^^^^^^^^^^^^^^
  File "D:\Project\venv\Lib\site-packages\import_export\admin.py", line 66, in changelist_view
    return super().changelist_view(request, extra_context)
           ~~~~~~~~~~~~~~~~~~~~~~~^^^^^^^^^^^^^^^^^^^^^^^^
  File "D:\Project\venv\Lib\site-packages\django\utils\decorators.py", line 48, in _wrapper
    return bound_method(*args, **kwargs)
  File "D:\Project\venv\Lib\site-packages\django\utils\decorators.py", line 188, in _view_wrapper
    result = _process_exception(request, e)
  File "D:\Project\venv\Lib\site-packages\django\utils\decorators.py", line 186, in _view_wrapper
    response = view_func(request, *args, **kwargs)
  File "D:\Project\venv\Lib\site-packages\django\contrib\admin\options.py", line 2032, in changelist_view
    response = self.response_action(
        request, queryset=cl.get_queryset(request)
    )
  File "D:\Project\venv\Lib\site-packages\django\contrib\admin\options.py", line 1664, in response_action
    response = func(self, request, queryset)
  File "D:\Project\base\admin.py", line 98, in generate_attendance
    generate_attendance_for_group(group.id)
    ~~~~~~~~~~~~~~~~~~~~~~~~~~~~~^^^^^^^^^^
  File "D:\Project\base\utils.py", line 29, in generate_attendance_for_group
    Attendance.objects.get_or_create(student=student, date=sana)
    ~~~~~~~~~~~~~~~~~~~~~~~~~~~~~~~~^^^^^^^^^^^^^^^^^^^^^^^^^^^^
  File "D:\Project\venv\Lib\site-packages\django\db\models\manager.py", line 87, in manager_method
    return getattr(self.get_queryset(), name)(*args, **kwargs)
           ~~~~~~~~~~~~~~~~~~~~~~~~~~~~~~~~~~^^^^^^^^^^^^^^^^^
  File "D:\Project\venv\Lib\site-packages\django\db\models\query.py", line 955, in get_or_create
    return self.create(**params), True
           ~~~~~~~~~~~^^^^^^^^^^
  File "D:\Project\venv\Lib\site-packages\django\db\models\query.py", line 679, in create
    obj.save(force_insert=True, using=self.db)
    ~~~~~~~~^^^^^^^^^^^^^^^^^^^^^^^^^^^^^^^^^^
  File "D:\Project\venv\Lib\site-packages\django\db\models\base.py", line 892, in save
    self.save_base(
    ~~~~~~~~~~~~~~^
        using=using,
        ^^^^^^^^^^^^
    ...<2 lines>...
        update_fields=update_fields,
        ^^^^^^^^^^^^^^^^^^^^^^^^^^^^
    )
    ^
  File "D:\Project\venv\Lib\site-packages\django\db\models\base.py", line 998, in save_base
    updated = self._save_table(
        raw,
    ...<4 lines>...
        update_fields,
    )
  File "D:\Project\venv\Lib\site-packages\django\db\models\base.py", line 1161, in _save_table
    results = self._do_insert(
        cls._base_manager, using, fields, returning_fields, raw
    )
  File "D:\Project\venv\Lib\site-packages\django\db\models\base.py", line 1202, in _do_insert
    return manager._insert(
           ~~~~~~~~~~~~~~~^
        [self],
        ^^^^^^^
    ...<3 lines>...
        raw=raw,
        ^^^^^^^^
    )
    ^
  File "D:\Project\venv\Lib\site-packages\django\db\models\manager.py", line 87, in manager_method
    return getattr(self.get_queryset(), name)(*args, **kwargs)
           ~~~~~~~~~~~~~~~~~~~~~~~~~~~~~~~~~~^^^^^^^^^^^^^^^^^
  File "D:\Project\venv\Lib\site-packages\django\db\models\query.py", line 1847, in _insert
    return query.get_compiler(using=using).execute_sql(returning_fields)
           ~~~~~~~~~~~~~~~~~~~~~~~~~~~~~~~~~~~~~~~~~~~^^^^^^^^^^^^^^^^^^
  File "D:\Project\venv\Lib\site-packages\django\db\models\sql\compiler.py", line 1836, in execute_sql
    cursor.execute(sql, params)
    ~~~~~~~~~~~~~~^^^^^^^^^^^^^
  File "D:\Project\venv\Lib\site-packages\django\db\backends\utils.py", line 122, in execute
    return super().execute(sql, params)
           ~~~~~~~~~~~~~~~^^^^^^^^^^^^^
  File "D:\Project\venv\Lib\site-packages\django\db\backends\utils.py", line 79, in execute
    return self._execute_with_wrappers(
           ~~~~~~~~~~~~~~~~~~~~~~~~~~~^
        sql, params, many=False, executor=self._execute
        ^^^^^^^^^^^^^^^^^^^^^^^^^^^^^^^^^^^^^^^^^^^^^^^
    )
    ^
  File "D:\Project\venv\Lib\site-packages\django\db\backends\utils.py", line 92, in _execute_with_wrappers
    return executor(sql, params, many, context)
  File "D:\Project\venv\Lib\site-packages\django\db\backends\utils.py", line 100, in _execute
    with self.db.wrap_database_errors:
         ^^^^^^^^^^^^^^^^^^^^^^^^^^^^
  File "D:\Project\venv\Lib\site-packages\django\db\utils.py", line 91, in __exit__
    raise dj_exc_value.with_traceback(traceback) from exc_value
  File "D:\Project\venv\Lib\site-packages\django\db\backends\utils.py", line 105, in _execute
    return self.cursor.execute(sql, params)
           ~~~~~~~~~~~~~~~~~~~^^^^^^^^^^^^^
  File "D:\Project\venv\Lib\site-packages\django\db\backends\mysql\base.py", line 76, in execute
    return self.cursor.execute(query, args)
           ~~~~~~~~~~~~~~~~~~~^^^^^^^^^^^^^
  File "D:\Project\venv\Lib\site-packages\MySQLdb\cursors.py", line 179, in execute
    res = self._query(mogrified_query)
  File "D:\Project\venv\Lib\site-packages\MySQLdb\cursors.py", line 330, in _query
    db.query(q)
    ~~~~~~~~^^^
  File "D:\Project\venv\Lib\site-packages\MySQLdb\connections.py", line 280, in query
    _mysql.connection.query(self, query)
    ~~~~~~~~~~~~~~~~~~~~~~~^^^^^^^^^^^^^
django.db.utils.IntegrityError: (1048, "Column 'status' cannot be null")
"POST /admin_settings_page/base/group/ HTTP/1.1" 500 266629
